Workbook

Sheet Read me
A1: Box wing span and gap sweep: Group 10, W6 wing down-select
A2: First estimate, for concept evaluation. Built by docs/pdr/scripts/build_boxwing_sweep.py.
A4: What it does
A5: Sizes the aircraft (Raymer Ch. 3 fuel fractions, Breguet cruise, brief App. 2-3 rules, Task Spec 4.7 margins) for a conventional wing and a box wing at spans of 56-65 m and gaps h/b of 0.05-0.25. Engine, Mach, cabin and mission are the same in every case, so only the wing changes.
A7: Sheets
A8: Inputs: every assumption, yellow = editable. Sweep: one row per case. Matrix: span x gap tables and a chart. Weight sensitivity: how much extra structure the box wing can carry before it stops saving fuel.
A10: Method
A11: 1. Wing area S = MTOW / wing loading (iterated 25 times with MTOW; the last column of Sweep shows it has converged).
A12: 2. Drag polar CD = CD0 x (1 + cfin x h) + k x CL^2 / (pi x AR x e), AR = b^2 / S (total area). k = 1 for the conventional wing.
A13: 3. k(h/b) = (1 + 0.45 h/b) / (1.04 + 2.81 h/b), Prandtl's estimate for the box wing: 20-30 % less induced drag at h/b 0.10-0.15, as quoted by Frediani.
A14: 4. L/D is calibrated so the conventional 64 m wing gives the slide-10 value of 19; every other case is relative to that.
A15: 5. OWE/MTOW = 0.52 + wing-mass share x (b/64 - 1) [Raymer wing mass ~ AR^0.5 ~ b at fixed S] + box penalty (pen0 + pfin x h).
... A26: Torenbeek, E. (1982) Synthesis of Subsonic Airplane Design: wing fuel volume estimate.

Sheet Inputs
A1: Inputs: yellow cells can be changed; everything else updates
A3: Quantity | B3: Value | C3: Unit | D3: Source / note
A4: Mission and brief rules (same as Group10_Sizing.xlsx)
A5: Passengers (3-class MR) | B5: 300 | C5: - | D5: Brief
A6: Passenger mass incl. baggage | B6: 105 | C6: kg | D6: Brief App. 2
A7: Flight crew | B7: 2 | C7: - | D7: Brief App. 2
A8: Flight crew mass incl. baggage | B8: 95 | C8: kg | D8: Brief App. 2
A9: Cabin crew | B9: 11 | C9: - | D9: Brief App. 2
A10: Cabin crew mass incl. baggage | B10: 85 | C10: kg | D10: Brief App. 2
A11: Design range | B11: 5000 | C11: NM | D11: Brief
A12: Cruise Mach | B12: 0.85 | C12: - | D12: Same for every wing
A13: Speed of sound, 35,000 ft ISA | B13: 576.4 | C13: kt | D13: ISA
A14: Cruise SFC (before margin) | B14: 0.52 | C14: 1/h | D14: Same engine for every wing
A15: Engine bypass ratio | B15: 10 | C15: - | D15: Same engine
A16: L/D margin | B16: 0.985 | C16: - | D16: Task Spec 4.7
... A28: SAF (HEFA) density | B28: 0.75 | C28: kg/L | D28: As Sizing sheet
A29: Slide-10 baseline (anchor)
A30: Cruise L/D, conventional base case | B30: 19 | C30: - | D30: Slide 10 base case
A31: OWE/MTOW, conventional base case | B31: 0.52 | C31: - | D31: Slide 10 base case
A32: Span the base case is assumed to have | B32: 64 | C32: m | D32: Just inside the 65 m Code E gate limit
A33: Wing and aerodynamic assumptions (agree as a team)
A34: Wing loading at MTOW (total wing area) | B34: 600 | C34: kg/m2 | D34: Raymer typical jet transport; A330neo ~540, 787 ~680
A35: Zero-lift drag coefficient, conventional | B35: 0.017 | C35: - | D35: Typical widebody; only ratios matter after calibration
A36: Oswald efficiency, conventional | B36: 0.8 | C36: - | D36: Raymer typical
A37: Cruise CL, conventional | B37: 0.5 | C37: - | D37: Sets cruise altitude (see Sweep)
A38: Cruise CL, box wing | B38: 0.5 | C38: - | D38: Same as conventional for a fair test: the model has no buffet or drag-rise limit, so raising only this flatters the box wing
A39: Landing CLmax, conventional | B39: 2.6 | C39: - | D39: Slats + double-slotted flaps
A40: Landing CLmax, box wing | B40: 2.4 | C40: - | D40: Rear wing in front wing's downwash: more conservative
A41: MLW / MTOW | B41: 0.78 | C41: - | D41: A330-900 and 787-9 are ~0.76
A42: Zero-lift drag added per metre of gap (tip fins) | B42: 0.005 | C42: per m | D42: Fin wetted area ~10 m2 per m of h vs ~2000 m2 aircraft; no horizontal tail assumed to offset joints
A43: Wing mass as a share of MTOW | B43: 0.11 | C43: - | D43: Typical widebody
A44: Box wing fixed OWE/MTOW penalty (joints, stiffening) | B44: 0.004 | C44: - | D44: ASSUMPTION: biggest unknown, see Weight sensitivity
A45: Box wing OWE/MTOW penalty per metre of gap (tip fins) | B45: 0.0006 | C45: per m | D45: ASSUMPTION: ~0.01 total at h = 10 m
... A47: Usable tank factor (taper, spars, ribs) | B47: 0.85 | C47: - | D47: ASSUMPTION
A48: Derived (do not edit)
A49: g | B49: 9.81 | C49: m/s2
A50: Take-off and initial climb fraction | B50: =1-(2.7795+2.3126/$B$15)/1000 -> 0.99698924 | C50: - | D50: Brief App. 3
A51: Cruise true airspeed | B51: =$B$12*$B$13 -> 489.94 | C51: kt
A52: Payload + crew | B52: =$B$5*$B$6+$B$7*$B$8+$B$9*$B$10 -> 32625 | C52: kg
A53: Baseline wing area | B53: =Sweep!$P$5*1000/$B$34 -> 330.28341 | C53: m2 | D53: From the slide-10 baseline row
...

Sheet Sweep
A1: Box wing span and gap sweep (first estimate, for concept evaluation)
A2: Same engine, Mach, cabin and mission rules for every row; only the wing changes. k = Prandtl's box-wing estimate (1 + 0.45 h/b)/(1.04 + 2.81 h/b). Spans 56-65 m: Code E (<= 65 m) because a box wing does not fold; a conventional wing of 54 m or less does not close at 600 kg/m2.
A4: Config | B4: Span b (m) | C4: Gap h/b | D4: Gap h (m) | E4: Induced drag factor k | F4: Zero-lift drag factor | G4: OWE / MTOW | H4: Cruise CL | I4: Landing CLmax | J4: Wing area S, total (m2) | K4: Aspect ratio b2/S | L4: Aspect ratio per wing | M4: Cruise L/D (before margin) | N4: Equivalent monoplane span (m) | O4: Fuel / MTOW | P4: MTOW (t) | Q4: OWE (t) | R4: Mission fuel (t) | S4: Fuel volume, SAF (m3) | T4: Fuel vs slide-10 baseline | U4: Fuel vs conventional, same span | V4: Wing tank volume (m3) | W4: Share of fuel that fits in the wings | X4: Approach speed at MLW (kt) | Y4: Cruise altitude (ft) | Z4: Iteration change in MTOW (kg) | AA4: Sizing closes? | AC4: pass 1: S | AD4: pass 1: AR | AE4: pass 1: LD | AF4: pass 1: fcr | AG4: pass 1: fland | AH4: pass 1: trip | AI4: pass 1: enr | AJ4: pass 1: ovs | AK4: pass 1: w1 | AL4: pass 1: div | AM4: pass 1: hold | AN4: pass 1: app | AO4: pass 1: ff | AP4: pass 1: MTOW | AQ4: pass 2: S | AR4: pass 2: AR | AS4: pass 2: LD | AT4: pass 2: fcr | AU4: pass 2: fland | AV4: pass 2: trip | AW4: pass 2: enr | AX4: pass 2: ovs | AY4: pass 2: w1 | AZ4: pass 2: div | BA4: pass 2: hold | BB4: pass 2: app | BC4: pass 2: ff | BD4: pass 2: MTOW | BE4: pass 3: S | BF4: pass 3: AR | BG4: pass 3: LD | BH4: pass 3: fcr | BI4: pass 3: fland | BJ4: pass 3: trip | BK4: pass 3: enr | BL4: pass 3: ovs | BM4: pass 3: w1 | BN4: pass 3: div | BO4: pass 3: hold | BP4: pass 3: app | BQ4: pass 3: ff | BR4: pass 3: MTOW | BS4: pass 4: S | BT4: pass 4: AR | BU4: pass 4: LD | BV4: pass 4: fcr | BW4: pass 4: fland | BX4: pass 4: trip | BY4: pass 4: enr | BZ4: pass 4: ovs | CA4: pass 4: w1 | CB4: pass 4: div | CC4: pass 4: hold | CD4: pass 4: app | CE4: pass 4: ff | CF4: pass 4: MTOW | CG4: pass 5: S | CH4: pass 5: AR | CI4: pass 5: LD | CJ4: pass 5: fcr | CK4: pass 5: fland | CL4: pass 5: trip | CM4: pass 5: enr | CN4: pass 5: ovs | CO4: pass 5: w1 | CP4: pass 5: div | CQ4: pass 5: hold | CR4: pass 5: app | CS4: pass 5: ff | CT4: pass 5: MTOW | CU4: pass 6: S | CV4: pass 6: AR | CW4: pass 6: LD | CX4: pass 6: fcr | CY4: pass 6: fland | CZ4: pass 6: trip | DA4: pass 6: enr | DB4: pass 6: ovs | DC4: pass 6: w1 | DD4: pass 6: div | DE4: pass 6: hold | DF4: pass 6: app | DG4: pass 6: ff | DH4: pass 6: MTOW | DI4: pass 7: S | DJ4: pass 7: AR | DK4: pass 7: LD | DL4: pass 7: fcr | DM4: pass 7: fland | DN4: pass 7: trip | DO4: pass 7: enr | DP4: pass 7: ovs | DQ4: pass 7: w1 | DR4: pass 7: div | DS4: pass 7: hold | DT4: pass 7: app | DU4: pass 7: ff | DV4: pass 7: MTOW | DW4: pass 8: S | DX4: pass 8: AR | DY4: pass 8: LD | DZ4: pass 8: fcr | EA4: pass 8: fland | EB4: pass 8: trip | EC4: pass 8: enr | ED4: pass 8: ovs | EE4: pass 8: w1 | EF4: pass 8: div | EG4: pass 8: hold | EH4: pass 8: app | EI4: pass 8: ff | EJ4: pass 8: MTOW | EK4: pass 9: S | EL4: pass 9: AR | EM4: pass 9: LD | EN4: pass 9: fcr | EO4: pass 9: fland | EP4: pass 9: trip | EQ4: pass 9: enr | ER4: pass 9: ovs | ES4: pass 9: w1 | ET4: pass 9: div | EU4: pass 9: hold | EV4: pass 9: app | EW4: pass 9: ff | EX4: pass 9: MTOW | EY4: pass 10: S | EZ4: pass 10: AR | FA4: pass 10: LD | FB4: pass 10: fcr | FC4: pass 10: fland | FD4: pass 10: trip | FE4: pass 10: enr | FF4: pass 10: ovs | FG4: pass 10: w1 | FH4: pass 10: div | FI4: pass 10: hold | FJ4: pass 10: app | FK4: pass 10: ff | FL4: pass 10: MTOW | FM4: pass 11: S | FN4: pass 11: AR | FO4: pass 11: LD | FP4: pass 11: fcr | FQ4: pass 11: fland | FR4: pass 11: trip | FS4: pass 11: enr | FT4: pass 11: ovs | FU4: pass 11: w1 | FV4: pass 11: div | FW4: pass 11: hold | FX4: pass 11: app | FY4: pass 11: ff | FZ4: pass 11: MTOW | GA4: pass 12: S | GB4: pass 12: AR | GC4: pass 12: LD | GD4: pass 12: fcr | GE4: pass 12: fland | GF4: pass 12: trip | GG4: pass 12: enr | GH4: pass 12: ovs | GI4: pass 12: w1 | GJ4: pass 12: div | GK4: pass 12: hold | GL4: pass 12: app | GM4: pass 12: ff | GN4: pass 12: MTOW | GO4: pass 13: S | GP4: pass 13: AR | GQ4: pass 13: LD | GR4: pass 13: fcr | GS4: pass 13: fland | GT4: pass 13: trip | GU4: pass 13: enr | GV4: pass 13: ovs | GW4: pass 13: w1 | GX4: pass 13: div | GY4: pass 13: hold | GZ4: pass 13: app | HA4: pass 13: ff | HB4: pass 13: MTOW | HC4: pass 14: S | HD4: pass 14: AR | HE4: pass 14: LD | HF4: pass 14: fcr | HG4: pass 14: fland | HH4: pass 14: trip | HI4: pass 14: enr | HJ4: pass 14: ovs | HK4: pass 14: w1 | HL4: pass 14: div | HM4: pass 14: hold | HN4: pass 14: app | HO4: pass 14: ff | HP4: pass 14: MTOW | HQ4: pass 15: S | HR4: pass 15: AR | HS4: pass 15: LD | HT4: pass 15: fcr | HU4: pass 15: fland | HV4: pass 15: trip | HW4: pass 15: enr | HX4: pass 15: ovs | HY4: pass 15: w1 | HZ4: pass 15: div | IA4: pass 15: hold | IB4: pass 15: app | IC4: pass 15: ff | ID4: pass 15: MTOW | IE4: pass 16: S | IF4: pass 16: AR | IG4: pass 16: LD | IH4: pass 16: fcr | II4: pass 16: fland | IJ4: pass 16: trip | IK4: pass 16: enr | IL4: pass 16: ovs | IM4: pass 16: w1 | IN4: pass 16: div | IO4: pass 16: hold | IP4: pass 16: app | IQ4: pass 16: ff | IR4: pass 16: MTOW | IS4: pass 17: S | IT4: pass 17: AR | IU4: pass 17: LD | IV4: pass 17: fcr | IW4: pass 17: fland | IX4: pass 17: trip | IY4: pass 17: enr | IZ4: pass 17: ovs | JA4: pass 17: w1 | JB4: pass 17: div | JC4: pass 17: hold | JD4: pass 17: app | JE4: pass 17: ff | JF4: pass 17: MTOW | JG4: pass 18: S | JH4: pass 18: AR | JI4: pass 18: LD | JJ4: pass 18: fcr | JK4: pass 18: fland | JL4: pass 18: trip | JM4: pass 18: enr | JN4: pass 18: ovs | JO4: pass 18: w1 | JP4: pass 18: div | JQ4: pass 18: hold | JR4: pass 18: app | JS4: pass 18: ff | JT4: pass 18: MTOW | JU4: pass 19: S | JV4: pass 19: AR | JW4: pass 19: LD | JX4: pass 19: fcr | JY4: pass 19: fland | JZ4: pass 19: trip | KA4: pass 19: enr | KB4: pass 19: ovs | KC4: pass 19: w1 | KD4: pass 19: div | KE4: pass 19: hold | KF4: pass 19: app | KG4: pass 19: ff | KH4: pass 19: MTOW | KI4: pass 20: S | KJ4: pass 20: AR | KK4: pass 20: LD | KL4: pass 20: fcr | KM4: pass 20: fland | KN4: pass 20: trip | KO4: pass 20: enr | KP4: pass 20: ovs | KQ4: pass 20: w1 | KR4: pass 20: div | KS4: pass 20: hold | KT4: pass 20: app | KU4: pass 20: ff | KV4: pass 20: MTOW | KW4: pass 21: S | KX4: pass 21: AR | KY4: pass 21: LD | KZ4: pass 21: fcr | LA4: pass 21: fland | LB4: pass 21: trip | LC4: pass 21: enr | LD4: pass 21: ovs | LE4: pass 21: w1 | LF4: pass 21: div | LG4: pass 21: hold | LH4: pass 21: app | LI4: pass 21: ff | LJ4: pass 21: MTOW | LK4: pass 22: S | LL4: pass 22: AR | LM4: pass 22: LD | LN4: pass 22: fcr | LO4: pass 22: fland | LP4: pass 22: trip | LQ4: pass 22: enr | LR4: pass 22: ovs | LS4: pass 22: w1 | LT4: pass 22: div | LU4: pass 22: hold | LV4: pass 22: app | LW4: pass 22: ff | LX4: pass 22: MTOW | LY4: pass 23: S | LZ4: pass 23: AR | MA4: pass 23: LD | MB4: pass 23: fcr | MC4: pass 23: fland | MD4: pass 23: trip | ME4: pass 23: enr | MF4: pass 23: ovs | MG4: pass 23: w1 | MH4: pass 23: div | MI4: pass 23: hold | MJ4: pass 23: app | MK4: pass 23: ff | ML4: pass 23: MTOW | MM4: pass 24: S | MN4: pass 24: AR | MO4: pass 24: LD | MP4: pass 24: fcr | MQ4: pass 24: fland | MR4: pass 24: trip | MS4: pass 24: enr | MT4: pass 24: ovs | MU4: pass 24: w1 | MV4: pass 24: div | MW4: pass 24: hold | MX4: pass 24: app | MY4: pass 24: ff | MZ4: pass 24: MTOW | NA4: pass 25: S | NB4: pass 25: AR | NC4: pass 25: LD | ND4: pass 25: fcr | NE4: pass 25: fland | NF4: pass 25: trip | NG4: pass 25: enr | NH4: pass 25: ovs | NI4: pass 25: w1 | NJ4: pass 25: div | NK4: pass 25: hold | NL4: pass 25: app | NM4: pass 25: ff | NN4: pass 25: MTOW
A5: Slide-10 baseline | B5: 64 | C5: 0 | D5: =B5*C5 -> 0 | E5: =IF(C5=0,1,(1+0.45*C5)/(1.04+2.81*C5)) -> 1 | F5: =1+Inputs!$B$42*D5 -> 1 | G5: =Inputs!$B$31 -> 0.52 | H5: =Inputs!$B$37 -> 0.5 | I5: =Inputs!$B$39 -> 2.6 | J5: =NN5/Inputs!$B$34 -> 330.28341 | K5: =B5^2/J5 -> 12.401471 | L5: =K5 -> 12.401471 | M5: =NC5 -> 19 | O5: =NM5 -> 0.31536866 | P5: =NN5/1000 -> 198.17004 | Q5: =G5*NN5/1000 -> 103.04842 | R5: =NM5*NN5/1000 -> 62.496622 | S5: =NM5*NN5/Inputs!$B$28/1000 -> 83.328829 | T5: =R5/Sweep!$R$5-1 -> 0 | U5: =R5/SUMIFS(Sweep!$R:$R,Sweep!$A:$A,"Conventional",Sweep!$B:$B,B5)-1 -> -3.3051339e-13 | V5: =1*0.54*(J5/1)^1.5/SQRT(L5)*Inputs!$B$46*Inputs!$B$47 -> 86.059518 | W5: =MIN(1,V5/S5) -> 1 | X5: =1.23*SQRT(2*Inputs!$B$41*NN5*Inputs!$B$49/(1.225*J5*I5))/0.5144 -> 128.38724 | Y5: =(11000+6341.6*LN(0.36392/(2*Inputs!$B$50*Inputs!$B$18*(1+ND5)/2*Inputs!$B$34*Inputs!$B$49/((Inputs!$B$12*295.07)^2*H5))))/0.3048 -> 38661.982 | Z5: =NN5-MZ5 -> 0 | AA5: =IF(ABS(NN5-MZ5)<10,"Yes","No") -> Yes | AC5: =Inputs!$B$52/(1-0.3154-G5)/Inputs!$B$34 -> 330.34629 | AD5: =B5^2/AC5 -> 12.39911 | AE5: =Inputs!$B$30 -> 19 | AF5: =EXP(-Inputs!$B$11*Inputs!$B$14*Inputs!$B$17/(Inputs!$B$51*AE5*Inputs!$B$16)) -> 0.74990367 | AG5: =Inputs!$B$50*Inputs!$B$18*AF5*Inputs!$B$19 -> 0.73274905 | AH5: =1-AG5 -> 0.26725095 | AI5: =Inputs!$B$20*AH5 -> 0.0080175286 | AJ5: =0.8*(1-Inputs!$B$50)*(AG5-AI5) -> 0.0017455941 | AK5: =AG5-AI5-AJ5 -> 0.72298593 | AL5: =AK5*(1-Inputs!$B$18*EXP(-Inputs!$B$21*Inputs!$B$14*Inputs!$B$17/(Inputs!$B$22*Inputs!$B$23*Inputs!$B$24*AE5*Inputs!$B$16))*Inputs!$B$19) -> 0.026351905 | AM5: =(AK5-AL5)*(1-EXP(-Inputs!$B$25*Inputs!$B$14*Inputs!$B$17*Inputs!$B$26/(AE5*Inputs!$B$16/0.866))) -> 0.0076143057 | AN5: =(AK5-AL5-AM5)*(1-Inputs!$B$19) -> 0.0034450986 | AO5: =(AH5+AI5+AJ5+AL5+AM5+AN5)*(1+Inputs!$B$27) -> 0.31536866 | AP5: =Inputs!$B$52/(1-AO5-G5) -> 198170.04 | AQ5: =AP5/Inputs!$B$34 -> 330.28341 | AR5: =B5^2/AQ5 -> 12.401471 | AS5: =Inputs!$B$30 -> 19 | AT5: =EXP(-Inputs!$B$11*Inputs!$B$14*Inputs!$B$17/(Inputs!$B$51*AS5*Inputs!$B$16)) -> 0.74990367 | AU5: =Inputs!$B$50*Inputs!$B$18*AT5*Inputs!$B$19 -> 0.73274905 | AV5: =1-AU5 -> 0.26725095 | AW5: =Inputs!$B$20*AV5 -> 0.0080175286 | AX5: =0.8*(1-Inputs!$B$50)*(AU5-AW5) -> 0.0017455941 | AY5: =AU5-AW5-AX5 -> 0.72298593 | AZ5: =AY5*(1-Inputs!$B$18*EXP(-Inputs!$B$21*Inputs!$B$14*Inputs!$B$17/(Inputs!$B$22*Inputs!$B$23*Inputs!$B$24*AS5*Inputs!$B$16))*Inputs!$B$19) -> 0.026351905 | BA5: =(AY5-AZ5)*(1-EXP(-Inputs!$B$25*Inputs!$B$14*Inputs!$B$17*Inputs!$B$26/(AS5*Inputs!$B$16/0.866))) -> 0.0076143057 | BB5: =(AY5-AZ5-BA5)*(1-Inputs!$B$19) -> 0.0034450986 | BC5: =(AV5+AW5+AX5+AZ5+BA5+BB5)*(1+Inputs!$B$27) -> 0.31536866 | BD5: =Inputs!$B$52/(1-BC5-G5) -> 198170.04 | BE5: =BD5/Inputs!$B$34 -> 330.28341 | BF5: =B5^2/BE5 -> 12.401471 | BG5: =Inputs!$B$30 -> 19 | BH5: =EXP(-Inputs!$B$11*Inputs!$B$14*Inputs!$B$17/(Inputs!$B$51*BG5*Inputs!$B$16)) -> 0.74990367 | BI5: =Inputs!$B$50*Inputs!$B$18*BH5*Inputs!$B$19 -> 0.73274905 | BJ5: =1-BI5 -> 0.26725095 | BK5: =Inputs!$B$20*BJ5 -> 0.0080175286 | BL5: =0.8*(1-Inputs!$B$50)*(BI5-BK5) -> 0.0017455941 | BM5: =BI5-BK5-BL5 -> 0.72298593 | BN5: =BM5*(1-Inputs!$B$18*EXP(-Inputs!$B$21*Inputs!$B$14*Inputs!$B$17/(Inputs!$B$22*Inputs!$B$23*Inputs!$B$24*BG5*Inputs!$B$16))*Inputs!$B$19) -> 0.026351905 | BO5: =(BM5-BN5)*(1-EXP(-Inputs!$B$25*Inputs!$B$14*Inputs!$B$17*Inputs!$B$26/(BG5*Inputs!$B$16/0.866))) -> 0.0076143057 | BP5: =(BM5-BN5-BO5)*(1-Inputs!$B$19) -> 0.0034450986 | BQ5: =(BJ5+BK5+BL5+BN5+BO5+BP5)*(1+Inputs!$B$27) -> 0.31536866 | BR5: =Inputs!$B$52/(1-BQ5-G5) -> 198170.04 | BS5: =BR5/Inputs!$B$34 -> 330.28341 | BT5: =B5^2/BS5 -> 12.401471 | BU5: =Inputs!$B$30 -> 19 | BV5: =EXP(-Inputs!$B$11*Inputs!$B$14*Inputs!$B$17/(Inputs!$B$51*BU5*Inputs!$B$16)) -> 0.74990367 | BW5: =Inputs!$B$50*Inputs!$B$18*BV5*Inputs!$B$19 -> 0.73274905 | BX5: =1-BW5 -> 0.26725095 | BY5: =Inputs!$B$20*BX5 -> 0.0080175286 | BZ5: =0.8*(1-Inputs!$B$50)*(BW5-BY5) -> 0.0017455941 | CA5: =BW5-BY5-BZ5 -> 0.72298593 | CB5: =CA5*(1-Inputs!$B$18*EXP(-Inputs!$B$21*Inputs!$B$14*Inputs!$B$17/(Inputs!$B$22*Inputs!$B$23*Inputs!$B$24*BU5*Inputs!$B$16))*Inputs!$B$19) -> 0.026351905 | CC5: =(CA5-CB5)*(1-EXP(-Inputs!$B$25*Inputs!$B$14*Inputs!$B$17*Inputs!$B$26/(BU5*Inputs!$B$16/0.866))) -> 0.0076143057 | CD5: =(CA5-CB5-CC5)*(1-Inputs!$B$19) -> 0.0034450986 | CE5: =(BX5+BY5+BZ5+CB5+CC5+CD5)*(1+Inputs!$B$27) -> 0.31536866 | CF5: =Inputs!$B$52/(1-CE5-G5) -> 198170.04 | CG5: =CF5/Inputs!$B$34 -> 330.28341 | CH5: =B5^2/CG5 -> 12.401471 | CI5: =Inputs!$B$30 -> 19 | CJ5: =EXP(-Inputs!$B$11*Inputs!$B$14*Inputs!$B$17/(Inputs!$B$51*CI5*Inputs!$B$16)) -> 0.74990367 | CK5: =Inputs!$B$50*Inputs!$B$18*CJ5*Inputs!$B$19 -> 0.73274905 | CL5: =1-CK5 -> 0.26725095 | CM5: =Inputs!$B$20*CL5 -> 0.0080175286 | CN5: =0.8*(1-Inputs!$B$50)*(CK5-CM5) -> 0.0017455941 | CO5: =CK5-CM5-CN5 -> 0.72298593 | CP5: =CO5*(1-Inputs!$B$18*EXP(-Inputs!$B$21*Inputs!$B$14*Inputs!$B$17/(Inputs!$B$22*Inputs!$B$23*Inputs!$B$24*CI5*Inputs!$B$16))*Inputs!$B$19) -> 0.026351905 | CQ5: =(CO5-CP5)*(1-EXP(-Inputs!$B$25*Inputs!$B$14*Inputs!$B$17*Inputs!$B$26/(CI5*Inputs!$B$16/0.866))) -> 0.0076143057 | CR5: =(CO5-CP5-CQ5)*(1-Inputs!$B$19) -> 0.0034450986 | CS5: =(CL5+CM5+CN5+CP5+CQ5+CR5)*(1+Inputs!$B$27) -> 0.31536866 | CT5: =Inputs!$B$52/(1-CS5-G5) -> 198170.04 | CU5: =CT5/Inputs!$B$34 -> 330.28341 | CV5: =B5^2/CU5 -> 12.401471 | CW5: =Inputs!$B$30 -> 19 | CX5: =EXP(-Inputs!$B$11*Inputs!$B$14*Inputs!$B$17/(Inputs!$B$51*CW5*Inputs!$B$16)) -> 0.74990367 | CY5: =Inputs!$B$50*Inputs!$B$18*CX5*Inputs!$B$19 -> 0.73274905 | CZ5: =1-CY5 -> 0.26725095 | DA5: =Inputs!$B$20*CZ5 -> 0.0080175286 | DB5: =0.8*(1-Inputs!$B$50)*(CY5-DA5) -> 0.0017455941 | DC5: =CY5-DA5-DB5 -> 0.72298593 | DD5: =DC5*(1-Inputs!$B$18*EXP(-Inputs!$B$21*Inputs!$B$14*Inputs!$B$17/(Inputs!$B$22*Inputs!$B$23*Inputs!$B$24*CW5*Inputs!$B$16))*Inputs!$B$19) -> 0.026351905 | DE5: =(DC5-DD5)*(1-EXP(-Inputs!$B$25*Inputs!$B$14*Inputs!$B$17*Inputs!$B$26/(CW5*Inputs!$B$16/0.866))) -> 0.0076143057 | DF5: =(DC5-DD5-DE5)*(1-Inputs!$B$19) -> 0.0034450986 | DG5: =(CZ5+DA5+DB5+DD5+DE5+DF5)*(1+Inputs!$B$27) -> 0.31536866 | DH5: =Inputs!$B$52/(1-DG5-G5) -> 198170.04 | DI5: =DH5/Inputs!$B$34 -> 330.28341 | DJ5: =B5^2/DI5 -> 12.401471 | DK5: =Inputs!$B$30 -> 19 | DL5: =EXP(-Inputs!$B$11*Inputs!$B$14*Inputs!$B$17/(Inputs!$B$51*DK5*Inputs!$B$16)) -> 0.74990367 | DM5: =Inputs!$B$50*Inputs!$B$18*DL5*Inputs!$B$19 -> 0.73274905 | DN5: =1-DM5 -> 0.26725095 | DO5: =Inputs!$B$20*DN5 -> 0.0080175286 | DP5: =0.8*(1-Inputs!$B$50)*(DM5-DO5) -> 0.0017455941 | DQ5: =DM5-DO5-DP5 -> 0.72298593 | DR5: =DQ5*(1-Inputs!$B$18*EXP(-Inputs!$B$21*Inputs!$B$14*Inputs!$B$17/(Inputs!$B$22*Inputs!$B$23*Inputs!$B$24*DK5*Inputs!$B$16))*Inputs!$B$19) -> 0.026351905 | DS5: =(DQ5-DR5)*(1-EXP(-Inputs!$B$25*Inputs!$B$14*Inputs!$B$17*Inputs!$B$26/(DK5*Inputs!$B$16/0.866))) -> 0.0076143057 | DT5: =(DQ5-DR5-DS5)*(1-Inputs!$B$19) -> 0.0034450986 | DU5: =(DN5+DO5+DP5+DR5+DS5+DT5)*(1+Inputs!$B$27) -> 0.31536866 | DV5: =Inputs!$B$52/(1-DU5-G5) -> 198170.04 | DW5: =DV5/Inputs!$B$34 -> 330.28341 | DX5: =B5^2/DW5 -> 12.401471 | DY5: =Inputs!$B$30 -> 19 | DZ5: =EXP(-Inputs!$B$11*Inputs!$B$14*Inputs!$B$17/(Inputs!$B$51*DY5*Inputs!$B$16)) -> 0.74990367 | EA5: =Inputs!$B$50*Inputs!$B$18*DZ5*Inputs!$B$19 -> 0.73274905 | EB5: =1-EA5 -> 0.26725095 | EC5: =Inputs!$B$20*EB5 -> 0.0080175286 | ED5: =0.8*(1-Inputs!$B$50)*(EA5-EC5) -> 0.0017455941 | EE5: =EA5-EC5-ED5 -> 0.72298593 | EF5: =EE5*(1-Inputs!$B$18*EXP(-Inputs!$B$21*Inputs!$B$14*Inputs!$B$17/(Inputs!$B$22*Inputs!$B$23*Inputs!$B$24*DY5*Inputs!$B$16))*Inputs!$B$19) -> 0.026351905 | EG5: =(EE5-EF5)*(1-EXP(-Inputs!$B$25*Inputs!$B$14*Inputs!$B$17*Inputs!$B$26/(DY5*Inputs!$B$16/0.866))) -> 0.0076143057 | EH5: =(EE5-EF5-EG5)*(1-Inputs!$B$19) -> 0.0034450986 | EI5: =(EB5+EC5+ED5+EF5+EG5+EH5)*(1+Inputs!$B$27) -> 0.31536866 | EJ5: =Inputs!$B$52/(1-EI5-G5) -> 198170.04 | EK5: =EJ5/Inputs!$B$34 -> 330.28341 | EL5: =B5^2/EK5 -> 12.401471 | EM5: =Inputs!$B$30 -> 19 | EN5: =EXP(-Inputs!$B$11*Inputs!$B$14*Inputs!$B$17/(Inputs!$B$51*EM5*Inputs!$B$16)) -> 0.74990367 | EO5: =Inputs!$B$50*Inputs!$B$18*EN5*Inputs!$B$19 -> 0.73274905 | EP5: =1-EO5 -> 0.26725095 | EQ5: =Inputs!$B$20*EP5 -> 0.0080175286 | ER5: =0.8*(1-Inputs!$B$50)*(EO5-EQ5) -> 0.0017455941 | ES5: =EO5-EQ5-ER5 -> 0.72298593 | ET5: =ES5*(1-Inputs!$B$18*EXP(-Inputs!$B$21*Inputs!$B$14*Inputs!$B$17/(Inputs!$B$22*Inputs!$B$23*Inputs!$B$24*EM5*Inputs!$B$16))*Inputs!$B$19) -> 0.026351905 | EU5: =(ES5-ET5)*(1-EXP(-Inputs!$B$25*Inputs!$B$14*Inputs!$B$17*Inputs!$B$26/(EM5*Inputs!$B$16/0.866))) -> 0.0076143057 | EV5: =(ES5-ET5-EU5)*(1-Inputs!$B$19) -> 0.0034450986 | EW5: =(EP5+EQ5+ER5+ET5+EU5+EV5)*(1+Inputs!$B$27) -> 0.31536866 | EX5: =Inputs!$B$52/(1-EW5-G5) -> 198170.04 | EY5: =EX5/Inputs!$B$34 -> 330.28341 | EZ5: =B5^2/EY5 -> 12.401471 | FA5: =Inputs!$B$30 -> 19 | FB5: =EXP(-Inputs!$B$11*Inputs!$B$14*Inputs!$B$17/(Inputs!$B$51*FA5*Inputs!$B$16)) -> 0.74990367 | FC5: =Inputs!$B$50*Inputs!$B$18*FB5*Inputs!$B$19 -> 0.73274905 | FD5: =1-FC5 -> 0.26725095 | FE5: =Inputs!$B$20*FD5 -> 0.0080175286 | FF5: =0.8*(1-Inputs!$B$50)*(FC5-FE5) -> 0.0017455941 | FG5: =FC5-FE5-FF5 -> 0.72298593 | FH5: =FG5*(1-Inputs!$B$18*EXP(-Inputs!$B$21*Inputs!$B$14*Inputs!$B$17/(Inputs!$B$22*Inputs!$B$23*Inputs!$B$24*FA5*Inputs!$B$16))*Inputs!$B$19) -> 0.026351905 | FI5: =(FG5-FH5)*(1-EXP(-Inputs!$B$25*Inputs!$B$14*Inputs!$B$17*Inputs!$B$26/(FA5*Inputs!$B$16/0.866))) -> 0.0076143057 | FJ5: =(FG5-FH5-FI5)*(1-Inputs!$B$19) -> 0.0034450986 | FK5: =(FD5+FE5+FF5+FH5+FI5+FJ5)*(1+Inputs!$B$27) -> 0.31536866 | FL5: =Inputs!$B$52/(1-FK5-G5) -> 198170.04 | FM5: =FL5/Inputs!$B$34 -> 330.28341 | FN5: =B5^2/FM5 -> 12.401471 | FO5: =Inputs!$B$30 -> 19 | FP5: =EXP(-Inputs!$B$11*Inputs!$B$14*Inputs!$B$17/(Inputs!$B$51*FO5*Inputs!$B$16)) -> 0.74990367 | FQ5: =Inputs!$B$50*Inputs!$B$18*FP5*Inputs!$B$19 -> 0.73274905 | FR5: =1-FQ5 -> 0.26725095 | FS5: =Inputs!$B$20*FR5 -> 0.0080175286 | FT5: =0.8*(1-Inputs!$B$50)*(FQ5-FS5) -> 0.0017455941 | FU5: =FQ5-FS5-FT5 -> 0.72298593 | FV5: =FU5*(1-Inputs!$B$18*EXP(-Inputs!$B$21*Inputs!$B$14*Inputs!$B$17/(Inputs!$B$22*Inputs!$B$23*Inputs!$B$24*FO5*Inputs!$B$16))*Inputs!$B$19) -> 0.026351905 | FW5: =(FU5-FV5)*(1-EXP(-Inputs!$B$25*Inputs!$B$14*Inputs!$B$17*Inputs!$B$26/(FO5*Inputs!$B$16/0.866))) -> 0.0076143057 | FX5: =(FU5-FV5-FW5)*(1-Inputs!$B$19) -> 0.0034450986 | FY5: =(FR5+FS5+FT5+FV5+FW5+FX5)*(1+Inputs!$B$27) -> 0.31536866 | FZ5: =Inputs!$B$52/(1-FY5-G5) -> 198170.04 | GA5: =FZ5/Inputs!$B$34 -> 330.28341 | GB5: =B5^2/GA5 -> 12.401471 | GC5: =Inputs!$B$30 -> 19 | GD5: =EXP(-Inputs!$B$11*Inputs!$B$14*Inputs!$B$17/(Inputs!$B$51*GC5*Inputs!$B$16)) -> 0.74990367 | GE5: =Inputs!$B$50*Inputs!$B$18*GD5*Inputs!$B$19 -> 0.73274905 | GF5: =1-GE5 -> 0.26725095 | GG5: =Inputs!$B$20*GF5 -> 0.0080175286 | GH5: =0.8*(1-Inputs!$B$50)*(GE5-GG5) -> 0.0017455941 | GI5: =GE5-GG5-GH5 -> 0.72298593 | GJ5: =GI5*(1-Inputs!$B$18*EXP(-Inputs!$B$21*Inputs!$B$14*Inputs!$B$17/(Inputs!$B$22*Inputs!$B$23*Inputs!$B$24*GC5*Inputs!$B$16))*Inputs!$B$19) -> 0.026351905 | GK5: =(GI5-GJ5)*(1-EXP(-Inputs!$B$25*Inputs!$B$14*Inputs!$B$17*Inputs!$B$26/(GC5*Inputs!$B$16/0.866))) -> 0.0076143057 | GL5: =(GI5-GJ5-GK5)*(1-Inputs!$B$19) -> 0.0034450986 | GM5: =(GF5+GG5+GH5+GJ5+GK5+GL5)*(1+Inputs!$B$27) -> 0.31536866 | GN5: =Inputs!$B$52/(1-GM5-G5) -> 198170.04 | GO5: =GN5/Inputs!$B$34 -> 330.28341 | GP5: =B5^2/GO5 -> 12.401471 | GQ5: =Inputs!$B$30 -> 19 | GR5: =EXP(-Inputs!$B$11*Inputs!$B$14*Inputs!$B$17/(Inputs!$B$51*GQ5*Inputs!$B$16)) -> 0.74990367 | GS5: =Inputs!$B$50*Inputs!$B$18*GR5*Inputs!$B$19 -> 0.73274905 | GT5: =1-GS5 -> 0.26725095 | GU5: =Inputs!$B$20*GT5 -> 0.0080175286 | GV5: =0.8*(1-Inputs!$B$50)*(GS5-GU5) -> 0.0017455941 | GW5: =GS5-GU5-GV5 -> 0.72298593 | GX5: =GW5*(1-Inputs!$B$18*EXP(-Inputs!$B$21*Inputs!$B$14*Inputs!$B$17/(Inputs!$B$22*Inputs!$B$23*Inputs!$B$24*GQ5*Inputs!$B$16))*Inputs!$B$19) -> 0.026351905 | GY5: =(GW5-GX5)*(1-EXP(-Inputs!$B$25*Inputs!$B$14*Inputs!$B$17*Inputs!$B$26/(GQ5*Inputs!$B$16/0.866))) -> 0.0076143057 | GZ5: =(GW5-GX5-GY5)*(1-Inputs!$B$19) -> 0.0034450986 | HA5: =(GT5+GU5+GV5+GX5+GY5+GZ5)*(1+Inputs!$B$27) -> 0.31536866 | HB5: =Inputs!$B$52/(1-HA5-G5) -> 198170.04 | HC5: =HB5/Inputs!$B$34 -> 330.28341 | HD5: =B5^2/HC5 -> 12.401471 | HE5: =Inputs!$B$30 -> 19 | HF5: =EXP(-Inputs!$B$11*Inputs!$B$14*Inputs!$B$17/(Inputs!$B$51*HE5*Inputs!$B$16)) -> 0.74990367 | HG5: =Inputs!$B$50*Inputs!$B$18*HF5*Inputs!$B$19 -> 0.73274905 | HH5: =1-HG5 -> 0.26725095 | HI5: =Inputs!$B$20*HH5 -> 0.0080175286 | HJ5: =0.8*(1-Inputs!$B$50)*(HG5-HI5) -> 0.0017455941 | HK5: =HG5-HI5-HJ5 -> 0.72298593 | HL5: =HK5*(1-Inputs!$B$18*EXP(-Inputs!$B$21*Inputs!$B$14*Inputs!$B$17/(Inputs!$B$22*Inputs!$B$23*Inputs!$B$24*HE5*Inputs!$B$16))*Inputs!$B$19) -> 0.026351905 | HM5: =(HK5-HL5)*(1-EXP(-Inputs!$B$25*Inputs!$B$14*Inputs!$B$17*Inputs!$B$26/(HE5*Inputs!$B$16/0.866))) -> 0.0076143057 | HN5: =(HK5-HL5-HM5)*(1-Inputs!$B$19) -> 0.0034450986 | HO5: =(HH5+HI5+HJ5+HL5+HM5+HN5)*(1+Inputs!$B$27) -> 0.31536866 | HP5: =Inputs!$B$52/(1-HO5-G5) -> 198170.04 | HQ5: =HP5/Inputs!$B$34 -> 330.28341 | HR5: =B5^2/HQ5 -> 12.401471 | HS5: =Inputs!$B$30 -> 19 | HT5: =EXP(-Inputs!$B$11*Inputs!$B$14*Inputs!$B$17/(Inputs!$B$51*HS5*Inputs!$B$16)) -> 0.74990367 | HU5: =Inputs!$B$50*Inputs!$B$18*HT5*Inputs!$B$19 -> 0.73274905 | HV5: =1-HU5 -> 0.26725095 | HW5: =Inputs!$B$20*HV5 -> 0.0080175286 | HX5: =0.8*(1-Inputs!$B$50)*(HU5-HW5) -> 0.0017455941 | HY5: =HU5-HW5-HX5 -> 0.72298593 | HZ5: =HY5*(1-Inputs!$B$18*EXP(-Inputs!$B$21*Inputs!$B$14*Inputs!$B$17/(Inputs!$B$22*Inputs!$B$23*Inputs!$B$24*HS5*Inputs!$B$16))*Inputs!$B$19) -> 0.026351905 | IA5: =(HY5-HZ5)*(1-EXP(-Inputs!$B$25*Inputs!$B$14*Inputs!$B$17*Inputs!$B$26/(HS5*Inputs!$B$16/0.866))) -> 0.0076143057 | IB5: =(HY5-HZ5-IA5)*(1-Inputs!$B$19) -> 0.0034450986 | IC5: =(HV5+HW5+HX5+HZ5+IA5+IB5)*(1+Inputs!$B$27) -> 0.31536866 | ID5: =Inputs!$B$52/(1-IC5-G5) -> 198170.04 | IE5: =ID5/Inputs!$B$34 -> 330.28341 | IF5: =B5^2/IE5 -> 12.401471 | IG5: =Inputs!$B$30 -> 19 | IH5: =EXP(-Inputs!$B$11*Inputs!$B$14*Inputs!$B$17/(Inputs!$B$51*IG5*Inputs!$B$16)) -> 0.74990367 | II5: =Inputs!$B$50*Inputs!$B$18*IH5*Inputs!$B$19 -> 0.73274905 | IJ5: =1-II5 -> 0.26725095 | IK5: =Inputs!$B$20*IJ5 -> 0.0080175286 | IL5: =0.8*(1-Inputs!$B$50)*(II5-IK5) -> 0.0017455941 | IM5: =II5-IK5-IL5 -> 0.72298593 | IN5: =IM5*(1-Inputs!$B$18*EXP(-Inputs!$B$21*Inputs!$B$14*Inputs!$B$17/(Inputs!$B$22*Inputs!$B$23*Inputs!$B$24*IG5*Inputs!$B$16))*Inputs!$B$19) -> 0.026351905 | IO5: =(IM5-IN5)*(1-EXP(-Inputs!$B$25*Inputs!$B$14*Inputs!$B$17*Inputs!$B$26/(IG5*Inputs!$B$16/0.866))) -> 0.0076143057 | IP5: =(IM5-IN5-IO5)*(1-Inputs!$B$19) -> 0.0034450986 | IQ5: =(IJ5+IK5+IL5+IN5+IO5+IP5)*(1+Inputs!$B$27) -> 0.31536866 | IR5: =Inputs!$B$52/(1-IQ5-G5) -> 198170.04 | IS5: =IR5/Inputs!$B$34 -> 330.28341 | IT5: =B5^2/IS5 -> 12.401471 | IU5: =Inputs!$B$30 -> 19 | IV5: =EXP(-Inputs!$B$11*Inputs!$B$14*Inputs!$B$17/(Inputs!$B$51*IU5*Inputs!$B$16)) -> 0.74990367 | IW5: =Inputs!$B$50*Inputs!$B$18*IV5*Inputs!$B$19 -> 0.73274905 | IX5: =1-IW5 -> 0.26725095 | IY5: =Inputs!$B$20*IX5 -> 0.0080175286 | IZ5: =0.8*(1-Inputs!$B$50)*(IW5-IY5) -> 0.0017455941 | JA5: =IW5-IY5-IZ5 -> 0.72298593 | JB5: =JA5*(1-Inputs!$B$18*EXP(-Inputs!$B$21*Inputs!$B$14*Inputs!$B$17/(Inputs!$B$22*Inputs!$B$23*Inputs!$B$24*IU5*Inputs!$B$16))*Inputs!$B$19) -> 0.026351905 | JC5: =(JA5-JB5)*(1-EXP(-Inputs!$B$25*Inputs!$B$14*Inputs!$B$17*Inputs!$B$26/(IU5*Inputs!$B$16/0.866))) -> 0.0076143057 | JD5: =(JA5-JB5-JC5)*(1-Inputs!$B$19) -> 0.0034450986 | JE5: =(IX5+IY5+IZ5+JB5+JC5+JD5)*(1+Inputs!$B$27) -> 0.31536866 | JF5: =Inputs!$B$52/(1-JE5-G5) -> 198170.04 | JG5: =JF5/Inputs!$B$34 -> 330.28341 | JH5: =B5^2/JG5 -> 12.401471 | JI5: =Inputs!$B$30 -> 19 | JJ5: =EXP(-Inputs!$B$11*Inputs!$B$14*Inputs!$B$17/(Inputs!$B$51*JI5*Inputs!$B$16)) -> 0.74990367 | JK5: =Inputs!$B$50*Inputs!$B$18*JJ5*Inputs!$B$19 -> 0.73274905 | JL5: =1-JK5 -> 0.26725095 | JM5: =Inputs!$B$20*JL5 -> 0.0080175286 | JN5: =0.8*(1-Inputs!$B$50)*(JK5-JM5) -> 0.0017455941 | JO5: =JK5-JM5-JN5 -> 0.72298593 | JP5: =JO5*(1-Inputs!$B$18*EXP(-Inputs!$B$21*Inputs!$B$14*Inputs!$B$17/(Inputs!$B$22*Inputs!$B$23*Inputs!$B$24*JI5*Inputs!$B$16))*Inputs!$B$19) -> 0.026351905 | JQ5: =(JO5-JP5)*(1-EXP(-Inputs!$B$25*Inputs!$B$14*Inputs!$B$17*Inputs!$B$26/(JI5*Inputs!$B$16/0.866))) -> 0.0076143057 | JR5: =(JO5-JP5-JQ5)*(1-Inputs!$B$19) -> 0.0034450986 | JS5: =(JL5+JM5+JN5+JP5+JQ5+JR5)*(1+Inputs!$B$27) -> 0.31536866 | JT5: =Inputs!$B$52/(1-JS5-G5) -> 198170.04 | JU5: =JT5/Inputs!$B$34 -> 330.28341 | JV5: =B5^2/JU5 -> 12.401471 | JW5: =Inputs!$B$30 -> 19 | JX5: =EXP(-Inputs!$B$11*Inputs!$B$14*Inputs!$B$17/(Inputs!$B$51*JW5*Inputs!$B$16)) -> 0.74990367 | JY5: =Inputs!$B$50*Inputs!$B$18*JX5*Inputs!$B$19 -> 0.73274905 | JZ5: =1-JY5 -> 0.26725095 | KA5: =Inputs!$B$20*JZ5 -> 0.0080175286 | KB5: =0.8*(1-Inputs!$B$50)*(JY5-KA5) -> 0.0017455941 | KC5: =JY5-KA5-KB5 -> 0.72298593 | KD5: =KC5*(1-Inputs!$B$18*EXP(-Inputs!$B$21*Inputs!$B$14*Inputs!$B$17/(Inputs!$B$22*Inputs!$B$23*Inputs!$B$24*JW5*Inputs!$B$16))*Inputs!$B$19) -> 0.026351905 | KE5: =(KC5-KD5)*(1-EXP(-Inputs!$B$25*Inputs!$B$14*Inputs!$B$17*Inputs!$B$26/(JW5*Inputs!$B$16/0.866))) -> 0.0076143057 | KF5: =(KC5-KD5-KE5)*(1-Inputs!$B$19) -> 0.0034450986 | KG5: =(JZ5+KA5+KB5+KD5+KE5+KF5)*(1+Inputs!$B$27) -> 0.31536866 | KH5: =Inputs!$B$52/(1-KG5-G5) -> 198170.04 | KI5: =KH5/Inputs!$B$34 -> 330.28341 | KJ5: =B5^2/KI5 -> 12.401471 | KK5: =Inputs!$B$30 -> 19 | KL5: =EXP(-Inputs!$B$11*Inputs!$B$14*Inputs!$B$17/(Inputs!$B$51*KK5*Inputs!$B$16)) -> 0.74990367 | KM5: =Inputs!$B$50*Inputs!$B$18*KL5*Inputs!$B$19 -> 0.73274905 | KN5: =1-KM5 -> 0.26725095 | KO5: =Inputs!$B$20*KN5 -> 0.0080175286 | KP5: =0.8*(1-Inputs!$B$50)*(KM5-KO5) -> 0.0017455941 | KQ5: =KM5-KO5-KP5 -> 0.72298593 | KR5: =KQ5*(1-Inputs!$B$18*EXP(-Inputs!$B$21*Inputs!$B$14*Inputs!$B$17/(Inputs!$B$22*Inputs!$B$23*Inputs!$B$24*KK5*Inputs!$B$16))*Inputs!$B$19) -> 0.026351905 | KS5: =(KQ5-KR5)*(1-EXP(-Inputs!$B$25*Inputs!$B$14*Inputs!$B$17*Inputs!$B$26/(KK5*Inputs!$B$16/0.866))) -> 0.0076143057 | KT5: =(KQ5-KR5-KS5)*(1-Inputs!$B$19) -> 0.0034450986 | KU5: =(KN5+KO5+KP5+KR5+KS5+KT5)*(1+Inputs!$B$27) -> 0.31536866 | KV5: =Inputs!$B$52/(1-KU5-G5) -> 198170.04 | KW5: =KV5/Inputs!$B$34 -> 330.28341 | KX5: =B5^2/KW5 -> 12.401471 | KY5: =Inputs!$B$30 -> 19 | KZ5: =EXP(-Inputs!$B$11*Inputs!$B$14*Inputs!$B$17/(Inputs!$B$51*KY5*Inputs!$B$16)) -> 0.74990367 | LA5: =Inputs!$B$50*Inputs!$B$18*KZ5*Inputs!$B$19 -> 0.73274905 | LB5: =1-LA5 -> 0.26725095 | LC5: =Inputs!$B$20*LB5 -> 0.0080175286 | LD5: =0.8*(1-Inputs!$B$50)*(LA5-LC5) -> 0.0017455941 | LE5: =LA5-LC5-LD5 -> 0.72298593 | LF5: =LE5*(1-Inputs!$B$18*EXP(-Inputs!$B$21*Inputs!$B$14*Inputs!$B$17/(Inputs!$B$22*Inputs!$B$23*Inputs!$B$24*KY5*Inputs!$B$16))*Inputs!$B$19) -> 0.026351905 | LG5: =(LE5-LF5)*(1-EXP(-Inputs!$B$25*Inputs!$B$14*Inputs!$B$17*Inputs!$B$26/(KY5*Inputs!$B$16/0.866))) -> 0.0076143057 | LH5: =(LE5-LF5-LG5)*(1-Inputs!$B$19) -> 0.0034450986 | LI5: =(LB5+LC5+LD5+LF5+LG5+LH5)*(1+Inputs!$B$27) -> 0.31536866 | LJ5: =Inputs!$B$52/(1-LI5-G5) -> 198170.04 | LK5: =LJ5/Inputs!$B$34 -> 330.28341 | LL5: =B5^2/LK5 -> 12.401471 | LM5: =Inputs!$B$30 -> 19 | LN5: =EXP(-Inputs!$B$11*Inputs!$B$14*Inputs!$B$17/(Inputs!$B$51*LM5*Inputs!$B$16)) -> 0.74990367 | LO5: =Inputs!$B$50*Inputs!$B$18*LN5*Inputs!$B$19 -> 0.73274905 | LP5: =1-LO5 -> 0.26725095 | LQ5: =Inputs!$B$20*LP5 -> 0.0080175286 | LR5: =0.8*(1-Inputs!$B$50)*(LO5-LQ5) -> 0.0017455941 | LS5: =LO5-LQ5-LR5 -> 0.72298593 | LT5: =LS5*(1-Inputs!$B$18*EXP(-Inputs!$B$21*Inputs!$B$14*Inputs!$B$17/(Inputs!$B$22*Inputs!$B$23*Inputs!$B$24*LM5*Inputs!$B$16))*Inputs!$B$19) -> 0.026351905 | LU5: =(LS5-LT5)*(1-EXP(-Inputs!$B$25*Inputs!$B$14*Inputs!$B$17*Inputs!$B$26/(LM5*Inputs!$B$16/0.866))) -> 0.0076143057 | LV5: =(LS5-LT5-LU5)*(1-Inputs!$B$19) -> 0.0034450986 | LW5: =(LP5+LQ5+LR5+LT5+LU5+LV5)*(1+Inputs!$B$27) -> 0.31536866 | LX5: =Inputs!$B$52/(1-LW5-G5) -> 198170.04 | LY5: =LX5/Inputs!$B$34 -> 330.28341 | LZ5: =B5^2/LY5 -> 12.401471 | MA5: =Inputs!$B$30 -> 19 | MB5: =EXP(-Inputs!$B$11*Inputs!$B$14*Inputs!$B$17/(Inputs!$B$51*MA5*Inputs!$B$16)) -> 0.74990367 | MC5: =Inputs!$B$50*Inputs!$B$18*MB5*Inputs!$B$19 -> 0.73274905 | MD5: =1-MC5 -> 0.26725095 | ME5: =Inputs!$B$20*MD5 -> 0.0080175286 | MF5: =0.8*(1-Inputs!$B$50)*(MC5-ME5) -> 0.0017455941 | MG5: =MC5-ME5-MF5 -> 0.72298593 | MH5: =MG5*(1-Inputs!$B$18*EXP(-Inputs!$B$21*Inputs!$B$14*Inputs!$B$17/(Inputs!$B$22*Inputs!$B$23*Inputs!$B$24*MA5*Inputs!$B$16))*Inputs!$B$19) -> 0.026351905 | MI5: =(MG5-MH5)*(1-EXP(-Inputs!$B$25*Inputs!$B$14*Inputs!$B$17*Inputs!$B$26/(MA5*Inputs!$B$16/0.866))) -> 0.0076143057 | MJ5: =(MG5-MH5-MI5)*(1-Inputs!$B$19) -> 0.0034450986 | MK5: =(MD5+ME5+MF5+MH5+MI5+MJ5)*(1+Inputs!$B$27) -> 0.31536866 | ML5: =Inputs!$B$52/(1-MK5-G5) -> 198170.04 | MM5: =ML5/Inputs!$B$34 -> 330.28341 | MN5: =B5^2/MM5 -> 12.401471 | MO5: =Inputs!$B$30 -> 19 | MP5: =EXP(-Inputs!$B$11*Inputs!$B$14*Inputs!$B$17/(Inputs!$B$51*MO5*Inputs!$B$16)) -> 0.74990367 | MQ5: =Inputs!$B$50*Inputs!$B$18*MP5*Inputs!$B$19 -> 0.73274905 | MR5: =1-MQ5 -> 0.26725095 | MS5: =Inputs!$B$20*MR5 -> 0.0080175286 | MT5: =0.8*(1-Inputs!$B$50)*(MQ5-MS5) -> 0.0017455941 | MU5: =MQ5-MS5-MT5 -> 0.72298593 | MV5: =MU5*(1-Inputs!$B$18*EXP(-Inputs!$B$21*Inputs!$B$14*Inputs!$B$17/(Inputs!$B$22*Inputs!$B$23*Inputs!$B$24*MO5*Inputs!$B$16))*Inputs!$B$19) -> 0.026351905 | MW5: =(MU5-MV5)*(1-EXP(-Inputs!$B$25*Inputs!$B$14*Inputs!$B$17*Inputs!$B$26/(MO5*Inputs!$B$16/0.866))) -> 0.0076143057 | MX5: =(MU5-MV5-MW5)*(1-Inputs!$B$19) -> 0.0034450986 | MY5: =(MR5+MS5+MT5+MV5+MW5+MX5)*(1+Inputs!$B$27) -> 0.31536866 | MZ5: =Inputs!$B$52/(1-MY5-G5) -> 198170.04 | NA5: =MZ5/Inputs!$B$34 -> 330.28341 | NB5: =B5^2/NA5 -> 12.401471 | NC5: =Inputs!$B$30 -> 19 | ND5: =EXP(-Inputs!$B$11*Inputs!$B$14*Inputs!$B$17/(Inputs!$B$51*NC5*Inputs!$B$16)) -> 0.74990367 | NE5: =Inputs!$B$50*Inputs!$B$18*ND5*Inputs!$B$19 -> 0.73274905 | NF5: =1-NE5 -> 0.26725095 | NG5: =Inputs!$B$20*NF5 -> 0.0080175286 | NH5: =0.8*(1-Inputs!$B$50)*(NE5-NG5) -> 0.0017455941 | NI5: =NE5-NG5-NH5 -> 0.72298593 | NJ5: =NI5*(1-Inputs!$B$18*EXP(-Inputs!$B$21*Inputs!$B$14*Inputs!$B$17/(Inputs!$B$22*Inputs!$B$23*Inputs!$B$24*NC5*Inputs!$B$16))*Inputs!$B$19) -> 0.026351905 | NK5: =(NI5-NJ5)*(1-EXP(-Inputs!$B$25*Inputs!$B$14*Inputs!$B$17*Inputs!$B$26/(NC5*Inputs!$B$16/0.866))) -> 0.0076143057 | NL5: =(NI5-NJ5-NK5)*(1-Inputs!$B$19) -> 0.0034450986 | NM5: =(NF5+NG5+NH5+NJ5+NK5+NL5)*(1+Inputs!$B$27) -> 0.31536866 | NN5: =Inputs!$B$52/(1-NM5-G5) -> 198170.04
A6: Conventional | B6: 56 | C6: 0 | D6: =B6*C6 -> 0 | E6: =IF(C6=0,1,(1+0.45*C6)/(1.04+2.81*C6)) -> 1 | F6: =1+Inputs!$B$42*D6 -> 1 | G6: =Inputs!$B$31+Inputs!$B$43*(B6/Inputs!$B$32-1) -> 0.50625 | H6: =Inputs!$B$37 -> 0.5 | I6: =Inputs!$B$39 -> 2.6 | J6: =NN6/Inputs!$B$34 -> 381.10188 | K6: =B6^2/J6 -> 8.2287707 | L6: =K6 -> 8.2287707 | M6: =NC6 -> 16.343401 | N6: =B6/SQRT(E6) -> 56 | O6: =NM6 -> 0.35107162 | P6: =NN6/1000 -> 228.66113 | Q6: =G6*NN6/1000 -> 115.7597 | R6: =NM6*NN6/1000 -> 80.276432 | S6: =NM6*NN6/Inputs!$B$28/1000 -> 107.03524 | T6: =R6/Sweep!$R$5-1 -> 0.28449235 | U6: =R6/SUMIFS(Sweep!$R:$R,Sweep!$A:$A,"Conventional",Sweep!$B:$B,B6)-1 -> 0 | V6: =1*0.54*(J6/1)^1.5/SQRT(L6)*Inputs!$B$46*Inputs!$B$47 -> 130.9482 | W6: =MIN(1,V6/S6) -> 1 | X6: =1.23*SQRT(2*Inputs!$B$41*NN6*Inputs!$B$49/(1.225*J6*I6))/0.5144 -> 128.38724 | Y6: =(11000+6341.6*LN(0.36392/(2*Inputs!$B$50*Inputs!$B$18*(1+ND6)/2*Inputs!$B$34*Inputs!$B$49/((Inputs!$B$12*295.07)^2*H6))))/0.3048 -> 39073.543 | Z6: =NN6-MZ6 -> 3.7822323 | AA6: =IF(ABS(NN6-MZ6)<10,"Yes","No") -> Yes | AC6: =Inputs!$B$52/(1-0.3154-G6)/Inputs!$B$34 -> 304.87805 | AD6: =B6^2/AC6 -> 10.28608 | AE6: =Inputs!$B$54*H6/(Inputs!$B$35*F6+E6*H6^2/(PI()*AD6*Inputs!$B$36)) -> 17.82486 | AF6: =EXP(-Inputs!$B$11*Inputs!$B$14*Inputs!$B$17/(Inputs!$B$51*AE6*Inputs!$B$16)) -> 0.73580878 | AG6: =Inputs!$B$50*Inputs!$B$18*AF6*Inputs!$B$19 -> 0.71897658 | AH6: =1-AG6 -> 0.28102342 | AI6: =Inputs!$B$20*AH6 -> 0.0084307025 | AJ6: =0.8*(1-Inputs!$B$50)*(AG6-AI6) -> 0.0017114265 | AK6: =AG6-AI6-AJ6 -> 0.70883445 | AL6: =AK6*(1-Inputs!$B$18*EXP(-Inputs!$B$21*Inputs!$B$14*Inputs!$B$17/(Inputs!$B$22*Inputs!$B$23*Inputs!$B$24*AE6*Inputs!$B$16))*Inputs!$B$19) -> 0.026601302 | AM6: =(AK6-AL6)*(1-EXP(-Inputs!$B$25*Inputs!$B$14*Inputs!$B$17*Inputs!$B$26/(AE6*Inputs!$B$16/0.866))) -> 0.00794564 | AN6: =(AK6-AL6-AM6)*(1-Inputs!$B$19) -> 0.0033714376 | AO6: =(AH6+AI6+AJ6+AL6+AM6+AN6)*(1+Inputs!$B$27) -> 0.33007118 | AP6: =Inputs!$B$52/(1-AO6-G6) -> 199323.28 | AQ6: =AP6/Inputs!$B$34 -> 332.20547 | AR6: =B6^2/AQ6 -> 9.4399409 | AS6: =Inputs!$B$54*H6/(Inputs!$B$35*F6+E6*H6^2/(PI()*AR6*Inputs!$B$36)) -> 17.263777 | AT6: =EXP(-Inputs!$B$11*Inputs!$B$14*Inputs!$B$17/(Inputs!$B$51*AS6*Inputs!$B$16)) -> 0.72850871 | AU6: =Inputs!$B$50*Inputs!$B$18*AT6*Inputs!$B$19 -> 0.71184351 | AV6: =1-AU6 -> 0.28815649 | AW6: =Inputs!$B$20*AV6 -> 0.0086446947 | AX6: =0.8*(1-Inputs!$B$50)*(AU6-AW6) -> 0.0016937303 | AY6: =AU6-AW6-AX6 -> 0.70150509 | AZ6: =AY6*(1-Inputs!$B$18*EXP(-Inputs!$B$21*Inputs!$B$14*Inputs!$B$17/(Inputs!$B$22*Inputs!$B$23*Inputs!$B$24*AS6*Inputs!$B$16))*Inputs!$B$19) -> 0.026723842 | BA6: =(AY6-AZ6)*(1-EXP(-Inputs!$B$25*Inputs!$B$14*Inputs!$B$17*Inputs!$B$26/(AS6*Inputs!$B$16/0.866))) -> 0.0081127269 | BB6: =(AY6-AZ6-BA6)*(1-Inputs!$B$19) -> 0.0033333426 | BC6: =(AV6+AW6+AX6+AZ6+BA6+BB6)*(1+Inputs!$B$27) -> 0.33767482 | BD6: =Inputs!$B$52/(1-BC6-G6) -> 209033.88 | BE6: =BD6/Inputs!$B$34 -> 348.3898 | BF6: =B6^2/BE6 -> 9.0014117 | BG6: =Inputs!$B$54*H6/(Inputs!$B$35*F6+E6*H6^2/(PI()*BF6*Inputs!$B$36)) -> 16.947833 | BH6: =EXP(-Inputs!$B$11*Inputs!$B$14*Inputs!$B$17/(Inputs!$B$51*BG6*Inputs!$B$16)) -> 0.72421953 | BI6: =Inputs!$B$50*Inputs!$B$18*BH6*Inputs!$B$19 -> 0.70765245 | BJ6: =1-BI6 -> 0.29234755 | BK6: =Inputs!$B$20*BJ6 -> 0.0087704266 | BL6: =0.8*(1-Inputs!$B$50)*(BI6-BK6) -> 0.0016833328 | BM6: =BI6-BK6-BL6 -> 0.69719869 | BN6: =BM6*(1-Inputs!$B$18*EXP(-Inputs!$B$21*Inputs!$B$14*Inputs!$B$17/(Inputs!$B$22*Inputs!$B$23*Inputs!$B$24*BG6*Inputs!$B$16))*Inputs!$B$19) -> 0.026793708 | BO6: =(BM6-BN6)*(1-EXP(-Inputs!$B$25*Inputs!$B$14*Inputs!$B$17*Inputs!$B$26/(BG6*Inputs!$B$16/0.866))) -> 0.0082094466 | BP6: =(BM6-BN6-BO6)*(1-Inputs!$B$19) -> 0.0033109777 | BQ6: =(BJ6+BK6+BL6+BN6+BO6+BP6)*(1+Inputs!$B$27) -> 0.34213879 | BR6: =Inputs!$B$52/(1-BQ6-G6) -> 215188.57 | BS6: =BR6/Inputs!$B$34 -> 358.64762 | BT6: =B6^2/BS6 -> 8.7439587 | BU6: =Inputs!$B$54*H6/(Inputs!$B$35*F6+E6*H6^2/(PI()*BT6*Inputs!$B$36)) -> 16.753502 | BV6: =EXP(-Inputs!$B$11*Inputs!$B$14*Inputs!$B$17/(Inputs!$B$51*BU6*Inputs!$B$16)) -> 0.72151408 | BW6: =Inputs!$B$50*Inputs!$B$18*BV6*Inputs!$B$19 -> 0.70500889 | BX6: =1-BW6 -> 0.29499111 | BY6: =Inputs!$B$20*BX6 -> 0.0088497334 | BZ6: =0.8*(1-Inputs!$B$50)*(BW6-BY6) -> 0.0016767745 | CA6: =BW6-BY6-BZ6 -> 0.69448238 | CB6: =CA6*(1-Inputs!$B$18*EXP(-Inputs!$B$21*Inputs!$B$14*Inputs!$B$17/(Inputs!$B$22*Inputs!$B$23*Inputs!$B$24*BU6*Inputs!$B$16))*Inputs!$B$19) -> 0.026836959 | CC6: =(CA6-CB6)*(1-EXP(-Inputs!$B$25*Inputs!$B$14*Inputs!$B$17*Inputs!$B$26/(BU6*Inputs!$B$16/0.866))) -> 0.0082698974 | CD6: =(CA6-CB6-CC6)*(1-Inputs!$B$19) -> 0.0032968776 | CE6: =(BX6+BY6+BZ6+CB6+CC6+CD6)*(1+Inputs!$B$27) -> 0.34495312 | CF6: =Inputs!$B$52/(1-CE6-G6) -> 219258.63 | CG6: =CF6/Inputs!$B$34 -> 365.43105 | CH6: =B6^2/CG6 -> 8.5816463 | CI6: =Inputs!$B$54*H6/(Inputs!$B$35*F6+E6*H6^2/(PI()*CH6*Inputs!$B$36)) -> 16.627422 | CJ6: =EXP(-Inputs!$B$11*Inputs!$B$14*Inputs!$B$17/(Inputs!$B$51*CI6*Inputs!$B$16)) -> 0.71973053 | CK6: =Inputs!$B$50*Inputs!$B$18*CJ6*Inputs!$B$19 -> 0.70326614 | CL6: =1-CK6 -> 0.29673386 | CM6: =Inputs!$B$20*CL6 -> 0.0089020157 | CN6: =0.8*(1-Inputs!$B$50)*(CK6-CM6) -> 0.001672451 | CO6: =CK6-CM6-CN6 -> 0.69269168 | CP6: =CO6*(1-Inputs!$B$18*EXP(-Inputs!$B$21*Inputs!$B$14*Inputs!$B$17/(Inputs!$B$22*Inputs!$B$23*Inputs!$B$24*CI6*Inputs!$B$16))*Inputs!$B$19) -> 0.026865124 | CQ6: =(CO6-CP6)*(1-EXP(-Inputs!$B$25*Inputs!$B$14*Inputs!$B$17*Inputs!$B$26/(CI6*Inputs!$B$16/0.866))) -> 0.0083095127 | CR6: =(CO6-CP6-CQ6)*(1-Inputs!$B$19) -> 0.0032875852 | CS6: =(CL6+CM6+CN6+CP6+CQ6+CR6)*(1+Inputs!$B$27) -> 0.34680786 | CT6: =Inputs!$B$52/(1-CS6-G6) -> 222026.16 | CU6: =CT6/Inputs!$B$34 -> 370.0436 | CV6: =B6^2/CU6 -> 8.474677 | CW6: =Inputs!$B$54*H6/(Inputs!$B$35*F6+E6*H6^2/(PI()*CV6*Inputs!$B$36)) -> 16.542769 | CX6: =EXP(-Inputs!$B$11*Inputs!$B$14*Inputs!$B$17/(Inputs!$B$51*CW6*Inputs!$B$16)) -> 0.71852029 | CY6: =Inputs!$B$50*Inputs!$B$18*CX6*Inputs!$B$19 -> 0.70208359 | CZ6: =1-CY6 -> 0.29791641 | DA6: =Inputs!$B$20*CZ6 -> 0.0089374924 | DB6: =0.8*(1-Inputs!$B$50)*(CY6-DA6) -> 0.0016695172 | DC6: =CY6-DA6-DB6 -> 0.69147658 | DD6: =DC6*(1-Inputs!$B$18*EXP(-Inputs!$B$21*Inputs!$B$14*Inputs!$B$17/(Inputs!$B$22*Inputs!$B$23*Inputs!$B$24*CW6*Inputs!$B$16))*Inputs!$B$19) -> 0.026884079 | DE6: =(DC6-DD6)*(1-EXP(-Inputs!$B$25*Inputs!$B$14*Inputs!$B$17*Inputs!$B$26/(CW6*Inputs!$B$16/0.866))) -> 0.0083362871 | DF6: =(DC6-DD6-DE6)*(1-Inputs!$B$19) -> 0.0032812811 | DG6: =(CZ6+DA6+DB6+DD6+DE6+DF6)*(1+Inputs!$B$27) -> 0.34806614 | DH6: =Inputs!$B$52/(1-DG6-G6) -> 223943.83 | DI6: =DH6/Inputs!$B$34 -> 373.23971 | DJ6: =B6^2/DI6 -> 8.4021071 | DK6: =Inputs!$B$54*H6/(Inputs!$B$35*F6+E6*H6^2/(PI()*DJ6*Inputs!$B$36)) -> 16.484616 | DL6: =EXP(-Inputs!$B$11*Inputs!$B$14*Inputs!$B$17/(Inputs!$B$51*DK6*Inputs!$B$16)) -> 0.71768289 | DM6: =Inputs!$B$50*Inputs!$B$18*DL6*Inputs!$B$19 -> 0.70126534 | DN6: =1-DM6 -> 0.29873466 | DO6: =Inputs!$B$20*DN6 -> 0.0089620398 | DP6: =0.8*(1-Inputs!$B$50)*(DM6-DO6) -> 0.0016674873 | DQ6: =DM6-DO6-DP6 -> 0.69063581 | DR6: =DQ6*(1-Inputs!$B$18*EXP(-Inputs!$B$21*Inputs!$B$14*Inputs!$B$17/(Inputs!$B$22*Inputs!$B$23*Inputs!$B$24*DK6*Inputs!$B$16))*Inputs!$B$19) -> 0.026897119 | DS6: =(DQ6-DR6)*(1-EXP(-Inputs!$B$25*Inputs!$B$14*Inputs!$B$17*Inputs!$B$26/(DK6*Inputs!$B$16/0.866))) -> 0.0083547622 | DT6: =(DQ6-DR6-DS6)*(1-Inputs!$B$19) -> 0.0032769197 | DU6: =(DN6+DO6+DP6+DR6+DS6+DT6)*(1+Inputs!$B$27) -> 0.34893667 | DV6: =Inputs!$B$52/(1-DU6-G6) -> 225290.03 | DW6: =DV6/Inputs!$B$34 -> 375.48338 | DX6: =B6^2/DW6 -> 8.351901 | DY6: =Inputs!$B$54*H6/(Inputs!$B$35*F6+E6*H6^2/(PI()*DX6*Inputs!$B$36)) -> 16.444036 | DZ6: =EXP(-Inputs!$B$11*Inputs!$B$14*Inputs!$B$17/(Inputs!$B$51*DY6*Inputs!$B$16)) -> 0.71709562 | EA6: =Inputs!$B$50*Inputs!$B$18*DZ6*Inputs!$B$19 -> 0.7006915 | EB6: =1-EA6 -> 0.2993085 | EC6: =Inputs!$B$20*EB6 -> 0.0089792549 | ED6: =0.8*(1-Inputs!$B$50)*(EA6-EC6) -> 0.0016660637 | EE6: =EA6-EC6-ED6 -> 0.69004618 | EF6: =EE6*(1-Inputs!$B$18*EXP(-Inputs!$B$21*Inputs!$B$14*Inputs!$B$17/(Inputs!$B$22*Inputs!$B$23*Inputs!$B$24*DY6*Inputs!$B$16))*Inputs!$B$19) -> 0.026906228 | EG6: =(EE6-EF6)*(1-EXP(-Inputs!$B$25*Inputs!$B$14*Inputs!$B$17*Inputs!$B$26/(DY6*Inputs!$B$16/0.866))) -> 0.0083676941 | EH6: =(EE6-EF6-EG6)*(1-Inputs!$B$19) -> 0.0032738613 | EI6: =(EB6+EC6+ED6+EF6+EG6+EH6)*(1+Inputs!$B$27) -> 0.3495471 | EJ6: =Inputs!$B$52/(1-EI6-G6) -> 226243.72 | EK6: =EJ6/Inputs!$B$34 -> 377.07287 | EL6: =B6^2/EK6 -> 8.3166948 | EM6: =Inputs!$B$54*H6/(Inputs!$B$35*F6+E6*H6^2/(PI()*EL6*Inputs!$B$36)) -> 16.415408 | EN6: =EXP(-Inputs!$B$11*Inputs!$B$14*Inputs!$B$17/(Inputs!$B$51*EM6*Inputs!$B$16)) -> 0.71667986 | EO6: =Inputs!$B$50*Inputs!$B$18*EN6*Inputs!$B$19 -> 0.70028526 | EP6: =1-EO6 -> 0.29971474 | EQ6: =Inputs!$B$20*EP6 -> 0.0089914422 | ER6: =0.8*(1-Inputs!$B$50)*(EO6-EQ6) -> 0.0016650558 | ES6: =EO6-EQ6-ER6 -> 0.68962876 | ET6: =ES6*(1-Inputs!$B$18*EXP(-Inputs!$B$21*Inputs!$B$14*Inputs!$B$17/(Inputs!$B$22*Inputs!$B$23*Inputs!$B$24*EM6*Inputs!$B$16))*Inputs!$B$19) -> 0.026912658 | EU6: =(ES6-ET6)*(1-EXP(-Inputs!$B$25*Inputs!$B$14*Inputs!$B$17*Inputs!$B$26/(EM6*Inputs!$B$16/0.866))) -> 0.0083768368 | EV6: =(ES6-ET6-EU6)*(1-Inputs!$B$19) -> 0.0032716963 | EW6: =(EP6+EQ6+ER6+ET6+EU6+EV6)*(1+Inputs!$B$27) -> 0.34997923 | EX6: =Inputs!$B$52/(1-EW6-G6) -> 226923.73 | EY6: =EX6/Inputs!$B$34 -> 378.20622 | EZ6: =B6^2/EY6 -> 8.2917727 | FA6: =Inputs!$B$54*H6/(Inputs!$B$35*F6+E6*H6^2/(PI()*EZ6*Inputs!$B$36)) -> 16.395057 | FB6: =EXP(-Inputs!$B$11*Inputs!$B$14*Inputs!$B$17/(Inputs!$B$51*FA6*Inputs!$B$16)) -> 0.71638357 | FC6: =Inputs!$B$50*Inputs!$B$18*FB6*Inputs!$B$19 -> 0.69999574 | FD6: =1-FC6 -> 0.30000426 | FE6: =Inputs!$B$20*FD6 -> 0.0090001277 | FF6: =0.8*(1-Inputs!$B$50)*(FC6-FE6) -> 0.0016643376 | FG6: =FC6-FE6-FF6 -> 0.68933128 | FH6: =FG6*(1-Inputs!$B$18*EXP(-Inputs!$B$21*Inputs!$B$14*Inputs!$B$17/(Inputs!$B$22*Inputs!$B$23*Inputs!$B$24*FA6*Inputs!$B$16))*Inputs!$B$19) -> 0.026917232 | FI6: =(FG6-FH6)*(1-EXP(-Inputs!$B$25*Inputs!$B$14*Inputs!$B$17*Inputs!$B$26/(FA6*Inputs!$B$16/0.866))) -> 0.0083833462 | FJ6: =(FG6-FH6-FI6)*(1-Inputs!$B$19) -> 0.0032701535 | FK6: =(FD6+FE6+FF6+FH6+FI6+FJ6)*(1+Inputs!$B$27) -> 0.35028717 | FL6: =Inputs!$B$52/(1-FK6-G6) -> 227410.83 | FM6: =FL6/Inputs!$B$34 -> 379.01804 | FN6: =B6^2/FM6 -> 8.2740124 | FO6: =Inputs!$B$54*H6/(Inputs!$B$35*F6+E6*H6^2/(PI()*FN6*Inputs!$B$36)) -> 16.38051 | FP6: =EXP(-Inputs!$B$11*Inputs!$B$14*Inputs!$B$17/(Inputs!$B$51*FO6*Inputs!$B$16)) -> 0.7161714 | FQ6: =Inputs!$B$50*Inputs!$B$18*FP6*Inputs!$B$19 -> 0.69978843 | FR6: =1-FQ6 -> 0.30021157 | FS6: =Inputs!$B$20*FR6 -> 0.009006347 | FT6: =0.8*(1-Inputs!$B$50)*(FQ6-FS6) -> 0.0016638233 | FU6: =FQ6-FS6-FT6 -> 0.68911826 | FV6: =FU6*(1-Inputs!$B$18*EXP(-Inputs!$B$21*Inputs!$B$14*Inputs!$B$17/(Inputs!$B$22*Inputs!$B$23*Inputs!$B$24*FO6*Inputs!$B$16))*Inputs!$B$19) -> 0.026920502 | FW6: =(FU6-FV6)*(1-EXP(-Inputs!$B$25*Inputs!$B$14*Inputs!$B$17*Inputs!$B$26/(FO6*Inputs!$B$16/0.866))) -> 0.0083880041 | FX6: =(FU6-FV6-FW6)*(1-Inputs!$B$19) -> 0.0032690488 | FY6: =(FR6+FS6+FT6+FV6+FW6+FX6)*(1+Inputs!$B$27) -> 0.35050767 | FZ6: =Inputs!$B$52/(1-FY6-G6) -> 227760.89 | GA6: =FZ6/Inputs!$B$34 -> 379.60148 | GB6: =B6^2/GA6 -> 8.2612955 | GC6: =Inputs!$B$54*H6/(Inputs!$B$35*F6+E6*H6^2/(PI()*GB6*Inputs!$B$36)) -> 16.370072 | GD6: =EXP(-Inputs!$B$11*Inputs!$B$14*Inputs!$B$17/(Inputs!$B$51*GC6*Inputs!$B$16)) -> 0.71601897 | GE6: =Inputs!$B$50*Inputs!$B$18*GD6*Inputs!$B$19 -> 0.69963948 | GF6: =1-GE6 -> 0.30036052 | GG6: =Inputs!$B$20*GF6 -> 0.0090108155 | GH6: =0.8*(1-Inputs!$B$50)*(GE6-GG6) -> 0.0016634537 | GI6: =GE6-GG6-GH6 -> 0.68896521 | GJ6: =GI6*(1-Inputs!$B$18*EXP(-Inputs!$B$21*Inputs!$B$14*Inputs!$B$17/(Inputs!$B$22*Inputs!$B$23*Inputs!$B$24*GC6*Inputs!$B$16))*Inputs!$B$19) -> 0.026922849 | GK6: =(GI6-GJ6)*(1-EXP(-Inputs!$B$25*Inputs!$B$14*Inputs!$B$17*Inputs!$B$26/(GC6*Inputs!$B$16/0.866))) -> 0.0083913491 | GL6: =(GI6-GJ6-GK6)*(1-Inputs!$B$19) -> 0.0032682551 | GM6: =(GF6+GG6+GH6+GJ6+GK6+GL6)*(1+Inputs!$B$27) -> 0.35066609 | GN6: =Inputs!$B$52/(1-GM6-G6) -> 228013.06 | GO6: =GN6/Inputs!$B$34 -> 380.02177 | GP6: =B6^2/GO6 -> 8.2521588 | GQ6: =Inputs!$B$54*H6/(Inputs!$B$35*F6+E6*H6^2/(PI()*GP6*Inputs!$B$36)) -> 16.36256 | GR6: =EXP(-Inputs!$B$11*Inputs!$B$14*Inputs!$B$17/(Inputs!$B$51*GQ6*Inputs!$B$16)) -> 0.71590918 | GS6: =Inputs!$B$50*Inputs!$B$18*GR6*Inputs!$B$19 -> 0.6995322 | GT6: =1-GS6 -> 0.3004678 | GU6: =Inputs!$B$20*GT6 -> 0.0090140339 | GV6: =0.8*(1-Inputs!$B$50)*(GS6-GU6) -> 0.0016631876 | GW6: =GS6-GU6-GV6 -> 0.68885498 | GX6: =GW6*(1-Inputs!$B$18*EXP(-Inputs!$B$21*Inputs!$B$14*Inputs!$B$17/(Inputs!$B$22*Inputs!$B$23*Inputs!$B$24*GQ6*Inputs!$B$16))*Inputs!$B$19) -> 0.026924538 | GY6: =(GW6-GX6)*(1-EXP(-Inputs!$B$25*Inputs!$B$14*Inputs!$B$17*Inputs!$B$26/(GQ6*Inputs!$B$16/0.866))) -> 0.0083937574 | GZ6: =(GW6-GX6-GY6)*(1-Inputs!$B$19) -> 0.0032676834 | HA6: =(GT6+GU6+GV6+GX6+GY6+GZ6)*(1+Inputs!$B$27) -> 0.35078019 | HB6: =Inputs!$B$52/(1-HA6-G6) -> 228195.03 | HC6: =HB6/Inputs!$B$34 -> 380.32505 | HD6: =B6^2/HC6 -> 8.2455783 | HE6: =Inputs!$B$54*H6/(Inputs!$B$35*F6+E6*H6^2/(PI()*HD6*Inputs!$B$36)) -> 16.357144 | HF6: =EXP(-Inputs!$B$11*Inputs!$B$14*Inputs!$B$17/(Inputs!$B$51*HE6*Inputs!$B$16)) -> 0.71582996 | HG6: =Inputs!$B$50*Inputs!$B$18*HF6*Inputs!$B$19 -> 0.6994548 | HH6: =1-HG6 -> 0.3005452 | HI6: =Inputs!$B$20*HH6 -> 0.009016356 | HJ6: =0.8*(1-Inputs!$B$50)*(HG6-HI6) -> 0.0016629956 | HK6: =HG6-HI6-HJ6 -> 0.68877545 | HL6: =HK6*(1-Inputs!$B$18*EXP(-Inputs!$B$21*Inputs!$B$14*Inputs!$B$17/(Inputs!$B$22*Inputs!$B$23*Inputs!$B$24*HE6*Inputs!$B$16))*Inputs!$B$19) -> 0.026925756 | HM6: =(HK6-HL6)*(1-EXP(-Inputs!$B$25*Inputs!$B$14*Inputs!$B$17*Inputs!$B$26/(HE6*Inputs!$B$16/0.866))) -> 0.0083954946 | HN6: =(HK6-HL6-HM6)*(1-Inputs!$B$19) -> 0.003267271 | HO6: =(HH6+HI6+HJ6+HL6+HM6+HN6)*(1+Inputs!$B$27) -> 0.35086251 | HP6: =Inputs!$B$52/(1-HO6-G6) -> 228326.5 | HQ6: =HP6/Inputs!$B$34 -> 380.54417 | HR6: =B6^2/HQ6 -> 8.2408305 | HS6: =Inputs!$B$54*H6/(Inputs!$B$35*F6+E6*H6^2/(PI()*HR6*Inputs!$B$36)) -> 16.353234 | HT6: =EXP(-Inputs!$B$11*Inputs!$B$14*Inputs!$B$17/(Inputs!$B$51*HS6*Inputs!$B$16)) -> 0.71577273 | HU6: =Inputs!$B$50*Inputs!$B$18*HT6*Inputs!$B$19 -> 0.69939888 | HV6: =1-HU6 -> 0.30060112 | HW6: =Inputs!$B$20*HV6 -> 0.0090180335 | HX6: =0.8*(1-Inputs!$B$50)*(HU6-HW6) -> 0.0016628568 | HY6: =HU6-HW6-HX6 -> 0.68871799 | HZ6: =HY6*(1-Inputs!$B$18*EXP(-Inputs!$B$21*Inputs!$B$14*Inputs!$B$17/(Inputs!$B$22*Inputs!$B$23*Inputs!$B$24*HS6*Inputs!$B$16))*Inputs!$B$19) -> 0.026926636 | IA6: =(HY6-HZ6)*(1-EXP(-Inputs!$B$25*Inputs!$B$14*Inputs!$B$17*Inputs!$B$26/(HS6*Inputs!$B$16/0.866))) -> 0.0083967493 | IB6: =(HY6-HZ6-IA6)*(1-Inputs!$B$19) -> 0.003266973 | IC6: =(HV6+HW6+HX6+HZ6+IA6+IB6)*(1+Inputs!$B$27) -> 0.35092198 | ID6: =Inputs!$B$52/(1-IC6-G6) -> 228421.57 | IE6: =ID6/Inputs!$B$34 -> 380.70262 | IF6: =B6^2/IE6 -> 8.2374006 | IG6: =Inputs!$B$54*H6/(Inputs!$B$35*F6+E6*H6^2/(PI()*IF6*Inputs!$B$36)) -> 16.350407 | IH6: =EXP(-Inputs!$B$11*Inputs!$B$14*Inputs!$B$17/(Inputs!$B$51*IG6*Inputs!$B$16)) -> 0.71573136 | II6: =Inputs!$B$50*Inputs!$B$18*IH6*Inputs!$B$19 -> 0.69935845 | IJ6: =1-II6 -> 0.30064155 | IK6: =Inputs!$B$20*IJ6 -> 0.0090192465 | IL6: =0.8*(1-Inputs!$B$50)*(II6-IK6) -> 0.0016627565 | IM6: =II6-IK6-IL6 -> 0.68867645 | IN6: =IM6*(1-Inputs!$B$18*EXP(-Inputs!$B$21*Inputs!$B$14*Inputs!$B$17/(Inputs!$B$22*Inputs!$B$23*Inputs!$B$24*IG6*Inputs!$B$16))*Inputs!$B$19) -> 0.026927272 | IO6: =(IM6-IN6)*(1-EXP(-Inputs!$B$25*Inputs!$B$14*Inputs!$B$17*Inputs!$B$26/(IG6*Inputs!$B$16/0.866))) -> 0.0083976565 | IP6: =(IM6-IN6-IO6)*(1-Inputs!$B$19) -> 0.0032667576 | IQ6: =(IJ6+IK6+IL6+IN6+IO6+IP6)*(1+Inputs!$B$27) -> 0.35096499 | IR6: =Inputs!$B$52/(1-IQ6-G6) -> 228490.36 | IS6: =IR6/Inputs!$B$34 -> 380.81727 | IT6: =B6^2/IS6 -> 8.2349206 | IU6: =Inputs!$B$54*H6/(Inputs!$B$35*F6+E6*H6^2/(PI()*IT6*Inputs!$B$36)) -> 16.348362 | IV6: =EXP(-Inputs!$B$11*Inputs!$B$14*Inputs!$B$17/(Inputs!$B$51*IU6*Inputs!$B$16)) -> 0.71570142 | IW6: =Inputs!$B$50*Inputs!$B$18*IV6*Inputs!$B$19 -> 0.69932919 | IX6: =1-IW6 -> 0.30067081 | IY6: =Inputs!$B$20*IX6 -> 0.0090201242 | IZ6: =0.8*(1-Inputs!$B$50)*(IW6-IY6) -> 0.0016626839 | JA6: =IW6-IY6-IZ6 -> 0.68864639 | JB6: =JA6*(1-Inputs!$B$18*EXP(-Inputs!$B$21*Inputs!$B$14*Inputs!$B$17/(Inputs!$B$22*Inputs!$B$23*Inputs!$B$24*IU6*Inputs!$B$16))*Inputs!$B$19) -> 0.026927732 | JC6: =(JA6-JB6)*(1-EXP(-Inputs!$B$25*Inputs!$B$14*Inputs!$B$17*Inputs!$B$26/(IU6*Inputs!$B$16/0.866))) -> 0.0083983128 | JD6: =(JA6-JB6-JC6)*(1-Inputs!$B$19) -> 0.0032666017 | JE6: =(IX6+IY6+IZ6+JB6+JC6+JD6)*(1+Inputs!$B$27) -> 0.3509961 | JF6: =Inputs!$B$52/(1-JE6-G6) -> 228540.16 | JG6: =JF6/Inputs!$B$34 -> 380.90027 | JH6: =B6^2/JG6 -> 8.2331261 | JI6: =Inputs!$B$54*H6/(Inputs!$B$35*F6+E6*H6^2/(PI()*JH6*Inputs!$B$36)) -> 16.346882 | JJ6: =EXP(-Inputs!$B$11*Inputs!$B$14*Inputs!$B$17/(Inputs!$B$51*JI6*Inputs!$B$16)) -> 0.71567974 | JK6: =Inputs!$B$50*Inputs!$B$18*JJ6*Inputs!$B$19 -> 0.69930802 | JL6: =1-JK6 -> 0.30069198 | JM6: =Inputs!$B$20*JL6 -> 0.0090207595 | JN6: =0.8*(1-Inputs!$B$50)*(JK6-JM6) -> 0.0016626314 | JO6: =JK6-JM6-JN6 -> 0.68862463 | JP6: =JO6*(1-Inputs!$B$18*EXP(-Inputs!$B$21*Inputs!$B$14*Inputs!$B$17/(Inputs!$B$22*Inputs!$B$23*Inputs!$B$24*JI6*Inputs!$B$16))*Inputs!$B$19) -> 0.026928065 | JQ6: =(JO6-JP6)*(1-EXP(-Inputs!$B$25*Inputs!$B$14*Inputs!$B$17*Inputs!$B$26/(JI6*Inputs!$B$16/0.866))) -> 0.0083987879 | JR6: =(JO6-JP6-JQ6)*(1-Inputs!$B$19) -> 0.0032664889 | JS6: =(JL6+JM6+JN6+JP6+JQ6+JR6)*(1+Inputs!$B$27) -> 0.35101862 | JT6: =Inputs!$B$52/(1-JS6-G6) -> 228576.23 | JU6: =JT6/Inputs!$B$34 -> 380.96038 | JV6: =B6^2/JU6 -> 8.2318271 | JW6: =Inputs!$B$54*H6/(Inputs!$B$35*F6+E6*H6^2/(PI()*JV6*Inputs!$B$36)) -> 16.34581 | JX6: =EXP(-Inputs!$B$11*Inputs!$B$14*Inputs!$B$17/(Inputs!$B$51*JW6*Inputs!$B$16)) -> 0.71566405 | JY6: =Inputs!$B$50*Inputs!$B$18*JX6*Inputs!$B$19 -> 0.69929268 | JZ6: =1-JY6 -> 0.30070732 | KA6: =Inputs!$B$20*JZ6 -> 0.0090212196 | KB6: =0.8*(1-Inputs!$B$50)*(JY6-KA6) -> 0.0016625934 | KC6: =JY6-KA6-KB6 -> 0.68860887 | KD6: =KC6*(1-Inputs!$B$18*EXP(-Inputs!$B$21*Inputs!$B$14*Inputs!$B$17/(Inputs!$B$22*Inputs!$B$23*Inputs!$B$24*JW6*Inputs!$B$16))*Inputs!$B$19) -> 0.026928306 | KE6: =(KC6-KD6)*(1-EXP(-Inputs!$B$25*Inputs!$B$14*Inputs!$B$17*Inputs!$B$26/(JW6*Inputs!$B$16/0.866))) -> 0.0083991319 | KF6: =(KC6-KD6-KE6)*(1-Inputs!$B$19) -> 0.0032664071 | KG6: =(JZ6+KA6+KB6+KD6+KE6+KF6)*(1+Inputs!$B$27) -> 0.35103493 | KH6: =Inputs!$B$52/(1-KG6-G6) -> 228602.35 | KI6: =KH6/Inputs!$B$34 -> 381.00392 | KJ6: =B6^2/KI6 -> 8.2308865 | KK6: =Inputs!$B$54*H6/(Inputs!$B$35*F6+E6*H6^2/(PI()*KJ6*Inputs!$B$36)) -> 16.345034 | KL6: =EXP(-Inputs!$B$11*Inputs!$B$14*Inputs!$B$17/(Inputs!$B$51*KK6*Inputs!$B$16)) -> 0.71565268 | KM6: =Inputs!$B$50*Inputs!$B$18*KL6*Inputs!$B$19 -> 0.69928157 | KN6: =1-KM6 -> 0.30071843 | KO6: =Inputs!$B$20*KN6 -> 0.0090215529 | KP6: =0.8*(1-Inputs!$B$50)*(KM6-KO6) -> 0.0016625658 | KQ6: =KM6-KO6-KP6 -> 0.68859745 | KR6: =KQ6*(1-Inputs!$B$18*EXP(-Inputs!$B$21*Inputs!$B$14*Inputs!$B$17/(Inputs!$B$22*Inputs!$B$23*Inputs!$B$24*KK6*Inputs!$B$16))*Inputs!$B$19) -> 0.026928481 | KS6: =(KQ6-KR6)*(1-EXP(-Inputs!$B$25*Inputs!$B$14*Inputs!$B$17*Inputs!$B$26/(KK6*Inputs!$B$16/0.866))) -> 0.0083993811 | KT6: =(KQ6-KR6-KS6)*(1-Inputs!$B$19) -> 0.003266348 | KU6: =(KN6+KO6+KP6+KR6+KS6+KT6)*(1+Inputs!$B$27) -> 0.35104675 | KV6: =Inputs!$B$52/(1-KU6-G6) -> 228621.28 | KW6: =KV6/Inputs!$B$34 -> 381.03546 | KX6: =B6^2/KW6 -> 8.2302051 | KY6: =Inputs!$B$54*H6/(Inputs!$B$35*F6+E6*H6^2/(PI()*KX6*Inputs!$B$36)) -> 16.344472 | KZ6: =EXP(-Inputs!$B$11*Inputs!$B$14*Inputs!$B$17/(Inputs!$B$51*KY6*Inputs!$B$16)) -> 0.71564444 | LA6: =Inputs!$B$50*Inputs!$B$18*KZ6*Inputs!$B$19 -> 0.69927352 | LB6: =1-LA6 -> 0.30072648 | LC6: =Inputs!$B$20*LB6 -> 0.0090217943 | LD6: =0.8*(1-Inputs!$B$50)*(LA6-LC6) -> 0.0016625458 | LE6: =LA6-LC6-LD6 -> 0.68858918 | LF6: =LE6*(1-Inputs!$B$18*EXP(-Inputs!$B$21*Inputs!$B$14*Inputs!$B$17/(Inputs!$B$22*Inputs!$B$23*Inputs!$B$24*KY6*Inputs!$B$16))*Inputs!$B$19) -> 0.026928607 | LG6: =(LE6-LF6)*(1-EXP(-Inputs!$B$25*Inputs!$B$14*Inputs!$B$17*Inputs!$B$26/(KY6*Inputs!$B$16/0.866))) -> 0.0083995616 | LH6: =(LE6-LF6-LG6)*(1-Inputs!$B$19) -> 0.0032663051 | LI6: =(LB6+LC6+LD6+LF6+LG6+LH6)*(1+Inputs!$B$27) -> 0.35105531 | LJ6: =Inputs!$B$52/(1-LI6-G6) -> 228634.99 | LK6: =LJ6/Inputs!$B$34 -> 381.05832 | LL6: =B6^2/LK6 -> 8.2297115 | LM6: =Inputs!$B$54*H6/(Inputs!$B$35*F6+E6*H6^2/(PI()*LL6*Inputs!$B$36)) -> 16.344065 | LN6: =EXP(-Inputs!$B$11*Inputs!$B$14*Inputs!$B$17/(Inputs!$B$51*LM6*Inputs!$B$16)) -> 0.71563847 | LO6: =Inputs!$B$50*Inputs!$B$18*LN6*Inputs!$B$19 -> 0.69926769 | LP6: =1-LO6 -> 0.30073231 | LQ6: =Inputs!$B$20*LP6 -> 0.0090219692 | LR6: =0.8*(1-Inputs!$B$50)*(LO6-LQ6) -> 0.0016625314 | LS6: =LO6-LQ6-LR6 -> 0.68858319 | LT6: =LS6*(1-Inputs!$B$18*EXP(-Inputs!$B$21*Inputs!$B$14*Inputs!$B$17/(Inputs!$B$22*Inputs!$B$23*Inputs!$B$24*LM6*Inputs!$B$16))*Inputs!$B$19) -> 0.026928699 | LU6: =(LS6-LT6)*(1-EXP(-Inputs!$B$25*Inputs!$B$14*Inputs!$B$17*Inputs!$B$26/(LM6*Inputs!$B$16/0.866))) -> 0.0083996924 | LV6: =(LS6-LT6-LU6)*(1-Inputs!$B$19) -> 0.003266274 | LW6: =(LP6+LQ6+LR6+LT6+LU6+LV6)*(1+Inputs!$B$27) -> 0.35106151 | LX6: =Inputs!$B$52/(1-LW6-G6) -> 228644.93 | LY6: =LX6/Inputs!$B$34 -> 381.07488 | LZ6: =B6^2/LY6 -> 8.2293538 | MA6: =Inputs!$B$54*H6/(Inputs!$B$35*F6+E6*H6^2/(PI()*LZ6*Inputs!$B$36)) -> 16.34377 | MB6: =EXP(-Inputs!$B$11*Inputs!$B$14*Inputs!$B$17/(Inputs!$B$51*MA6*Inputs!$B$16)) -> 0.71563415 | MC6: =Inputs!$B$50*Inputs!$B$18*MB6*Inputs!$B$19 -> 0.69926347 | MD6: =1-MC6 -> 0.30073653 | ME6: =Inputs!$B$20*MD6 -> 0.009022096 | MF6: =0.8*(1-Inputs!$B$50)*(MC6-ME6) -> 0.0016625209 | MG6: =MC6-ME6-MF6 -> 0.68857885 | MH6: =MG6*(1-Inputs!$B$18*EXP(-Inputs!$B$21*Inputs!$B$14*Inputs!$B$17/(Inputs!$B$22*Inputs!$B$23*Inputs!$B$24*MA6*Inputs!$B$16))*Inputs!$B$19) -> 0.026928765 | MI6: =(MG6-MH6)*(1-EXP(-Inputs!$B$25*Inputs!$B$14*Inputs!$B$17*Inputs!$B$26/(MA6*Inputs!$B$16/0.866))) -> 0.0083997871 | MJ6: =(MG6-MH6-MI6)*(1-Inputs!$B$19) -> 0.0032662515 | MK6: =(MD6+ME6+MF6+MH6+MI6+MJ6)*(1+Inputs!$B$27) -> 0.351066 | ML6: =Inputs!$B$52/(1-MK6-G6) -> 228652.13 | MM6: =ML6/Inputs!$B$34 -> 381.08688 | MN6: =B6^2/MM6 -> 8.2290946 | MO6: =Inputs!$B$54*H6/(Inputs!$B$35*F6+E6*H6^2/(PI()*MN6*Inputs!$B$36)) -> 16.343556 | MP6: =EXP(-Inputs!$B$11*Inputs!$B$14*Inputs!$B$17/(Inputs!$B$51*MO6*Inputs!$B$16)) -> 0.71563102 | MQ6: =Inputs!$B$50*Inputs!$B$18*MP6*Inputs!$B$19 -> 0.69926041 | MR6: =1-MQ6 -> 0.30073959 | MS6: =Inputs!$B$20*MR6 -> 0.0090221878 | MT6: =0.8*(1-Inputs!$B$50)*(MQ6-MS6) -> 0.0016625133 | MU6: =MQ6-MS6-MT6 -> 0.6885757 | MV6: =MU6*(1-Inputs!$B$18*EXP(-Inputs!$B$21*Inputs!$B$14*Inputs!$B$17/(Inputs!$B$22*Inputs!$B$23*Inputs!$B$24*MO6*Inputs!$B$16))*Inputs!$B$19) -> 0.026928813 | MW6: =(MU6-MV6)*(1-EXP(-Inputs!$B$25*Inputs!$B$14*Inputs!$B$17*Inputs!$B$26/(MO6*Inputs!$B$16/0.866))) -> 0.0083998558 | MX6: =(MU6-MV6-MW6)*(1-Inputs!$B$19) -> 0.0032662352 | MY6: =(MR6+MS6+MT6+MV6+MW6+MX6)*(1+Inputs!$B$27) -> 0.35106926 | MZ6: =Inputs!$B$52/(1-MY6-G6) -> 228657.35 | NA6: =MZ6/Inputs!$B$34 -> 381.09558 | NB6: =B6^2/NA6 -> 8.2289068 | NC6: =Inputs!$B$54*H6/(Inputs!$B$35*F6+E6*H6^2/(PI()*NB6*Inputs!$B$36)) -> 16.343401 | ND6: =EXP(-Inputs!$B$11*Inputs!$B$14*Inputs!$B$17/(Inputs!$B$51*NC6*Inputs!$B$16)) -> 0.71562875 | NE6: =Inputs!$B$50*Inputs!$B$18*ND6*Inputs!$B$19 -> 0.69925819 | NF6: =1-NE6 -> 0.30074181 | NG6: =Inputs!$B$20*NF6 -> 0.0090222544 | NH6: =0.8*(1-Inputs!$B$50)*(NE6-NG6) -> 0.0016625078 | NI6: =NE6-NG6-NH6 -> 0.68857342 | NJ6: =NI6*(1-Inputs!$B$18*EXP(-Inputs!$B$21*Inputs!$B$14*Inputs!$B$17/(Inputs!$B$22*Inputs!$B$23*Inputs!$B$24*NC6*Inputs!$B$16))*Inputs!$B$19) -> 0.026928848 | NK6: =(NI6-NJ6)*(1-EXP(-Inputs!$B$25*Inputs!$B$14*Inputs!$B$17*Inputs!$B$26/(NC6*Inputs!$B$16/0.866))) -> 0.0083999056 | NL6: =(NI6-NJ6-NK6)*(1-Inputs!$B$19) -> 0.0032662234 | NM6: =(NF6+NG6+NH6+NJ6+NK6+NL6)*(1+Inputs!$B$27) -> 0.35107162 | NN6: =Inputs!$B$52/(1-NM6-G6) -> 228661.13
